{
 "cells": [
  {
   "cell_type": "markdown",
   "id": "4b9c3505-46d7-41e2-8a73-f935fc477b2e",
   "metadata": {},
   "source": [
    "## 前期准备\n",
    "\n",
    "alice 和 bob 节点分别启动 ray 集群。\n",
    "\n",
    "```\n",
    "ray start --head --node-ip-address=\"ip\" --port=\"port\" --include-dashboard=False --disable-usage-stats\n",
    "```\n",
    "\n",
    "屏幕输出中显示 <span style=\"color: #008A00\">Ray runtime started</span>，则说明 Ray 的主节点启动成功。"
   ]
  },
  {
   "cell_type": "markdown",
   "id": "48ef05a4-9b0c-462b-b492-59b3ed0a8daa",
   "metadata": {},
   "source": [
    "## 初始化 SecretFlow\n",
    "\n",
    "alice 和 bob 节点都需要初始化 secretflow，初始化语句只有在 self_party 上有区别。\n",
    "\n",
    "1. 分别使用 Ray 主节点的 node-ip-address 和 port 填充 sf.init 的 address 参数。\n",
    "2. parties 中 alice 和 bob 的 address 分别填可以被对方访问的地址，并且选择一个**未被占用的端口。**"
   ]
  },
  {
   "cell_type": "code",
   "execution_count": 1,
   "id": "8bb69b61-3c46-473d-bc09-63458d1d74c3",
   "metadata": {
    "execution": {
     "executionParty": "[\"1e1e72d3-844e-4ada-966e-d56bb5f217ed\",\"806a79e5-f708-4e3e-a0ff-e3ea0503a00a\"]",
     "shell.execute_reply.end": "2023-10-10T05:18:22.222093Z",
     "shell.execute_reply.started": "2023-10-10T05:18:20.669612Z",
     "to_execute": "2023-10-10T05:18:20.665Z"
    }
   },
   "outputs": [],
   "source": [
    "import secretflow as sf\n",
    "import spu\n",
    "\n",
    "network_conf = {\n",
    "    'parties': {\n",
    "        'alice': {\n",
    "            'address': 'alice:8080',\n",
    "        },\n",
    "        'bob': {\n",
    "            'address': 'bob:8080',\n",
    "        },\n",
    "    },\n",
    "}"
   ]
  },
  {
   "cell_type": "markdown",
   "id": "a96168de-6e3d-4867-a802-1f67729d47bf",
   "metadata": {},
   "source": [
    "### alice 和 bob 初始化\n",
    "\n",
    "<span style=\"color: #BA4081\">注意：下面初始化语句是分别只在对应的 alice 或 bob 节点执行的。除了初始化语句，后面所有代码，会被同时下发到 alice 和 bob 节点执行。</span>"
   ]
  },
  {
   "cell_type": "code",
   "execution_count": 2,
   "id": "115b9ebf-4d2c-4004-ad54-b79f4d6da2a6",
   "metadata": {
    "execution": {
     "executionParty": "[\"1e1e72d3-844e-4ada-966e-d56bb5f217ed\"]",
     "shell.execute_reply.end": "2023-10-10T05:18:24.412273Z",
     "shell.execute_reply.started": "2023-10-10T05:18:22.225927Z",
     "to_execute": "2023-10-10T05:18:20.666Z"
    }
   },
   "outputs": [
    {
     "data": {
      "text/html": [
       "<h4>Alice (You)'s Output:</h4>"
      ]
     },
     "metadata": {},
     "output_type": "display_data"
    },
    {
     "name": "stderr",
     "output_type": "stream",
     "text": [
      "2023-10-10 05:18:22,228\tINFO worker.py:1352 -- Connecting to existing Ray cluster at address: 172.21.0.2:6379...\n",
      "2023-10-10 05:18:22,253\tINFO worker.py:1529 -- Connected to Ray cluster. View the dashboard at \u001b[1m\u001b[32mhttp://172.21.0.2:8265 \u001b[39m\u001b[22m\n",
      "2023-10-10 05:18:22 INFO api.py:147 [alice] --  Started rayfed with {'CLUSTER_ADDRESSES': {'alice': 'alice:8080', 'bob': 'bob:8080'}, 'CURRENT_PARTY_NAME': 'alice', 'TLS_CONFIG': {}}\n",
      "2023-10-10 05:18:22 INFO cleanup.py:58 [alice] --  Start check sending thread.\n",
      "2023-10-10 05:18:22 INFO cleanup.py:67 [alice] --  Start check sending monitor thread.\n",
      "2023-10-10 05:18:23 INFO barriers.py:235 [alice] --  Succeeded to create receiver proxy actor.\n",
      "\u001b[2m\u001b[36m(ReceiverProxyActor pid=626)\u001b[0m 2023-10-10 05:18:23 INFO grpc_proxy.py:306 [alice] --  ReceiveProxy binding port 8080, options: (('grpc.enable_retries', 1), ('grpc.so_reuseport', 0), ('grpc.max_send_message_length', 524288000), ('grpc.max_receive_message_length', 524288000), ('grpc.service_config', '{\"methodConfig\": [{\"name\": [{\"service\": \"GrpcService\"}], \"retryPolicy\": {\"maxAttempts\": 5, \"initialBackoff\": \"5s\", \"maxBackoff\": \"30s\", \"backoffMultiplier\": 2, \"retryableStatusCodes\": [\"UNAVAILABLE\"]}}]}'))...\n",
      "\u001b[2m\u001b[36m(ReceiverProxyActor pid=626)\u001b[0m 2023-10-10 05:18:23 INFO grpc_proxy.py:326 [alice] --  Successfully start Grpc service without credentials.\n",
      "2023-10-10 05:18:24 INFO barriers.py:283 [alice] --  SenderProxyActor has successfully created.\n",
      "2023-10-10 05:18:24 INFO barriers.py:438 [alice] --  Try ping ['bob'] at 0 attemp, up to 3600 attemps.\n"
     ]
    }
   ],
   "source": [
    "sf.shutdown()\n",
    "sf.init(\n",
    "    address='127.0.0.1:6379',\n",
    "    cluster_config={**network_conf, 'self_party': 'alice'},\n",
    "    log_to_driver=True,\n",
    ")"
   ]
  },
  {
   "cell_type": "code",
   "execution_count": 2,
   "id": "fb953a01-f34e-4c29-a562-ee8c9975eb05",
   "metadata": {
    "execution": {
     "executionParty": "[\"806a79e5-f708-4e3e-a0ff-e3ea0503a00a\"]",
     "shell.execute_reply.end": "2023-10-10T05:18:24.510334Z",
     "shell.execute_reply.started": "2023-10-10T05:18:22.219985Z",
     "to_execute": "2023-10-10T05:18:20.666Z"
    }
   },
   "outputs": [
    {
     "data": {
      "text/html": [
       "<h4>Bob's Output:</h4>"
      ]
     },
     "metadata": {},
     "output_type": "display_data"
    },
    {
     "name": "stderr",
     "output_type": "stream",
     "text": [
      "2023-10-10 05:18:22,223\tINFO worker.py:1352 -- Connecting to existing Ray cluster at address: 172.21.0.3:6379...\n",
      "2023-10-10 05:18:22,249\tINFO worker.py:1529 -- Connected to Ray cluster. View the dashboard at \u001b[1m\u001b[32mhttp://172.21.0.3:8265 \u001b[39m\u001b[22m\n",
      "2023-10-10 05:18:22 INFO api.py:147 [bob] --  Started rayfed with {'CLUSTER_ADDRESSES': {'alice': 'alice:8080', 'bob': 'bob:8080'}, 'CURRENT_PARTY_NAME': 'bob', 'TLS_CONFIG': {}}\n",
      "2023-10-10 05:18:22 INFO cleanup.py:58 [bob] --  Start check sending thread.\n",
      "2023-10-10 05:18:22 INFO cleanup.py:67 [bob] --  Start check sending monitor thread.\n",
      "2023-10-10 05:18:23 INFO barriers.py:235 [bob] --  Succeeded to create receiver proxy actor.\n",
      "\u001b[2m\u001b[36m(ReceiverProxyActor pid=598)\u001b[0m 2023-10-10 05:18:23 INFO grpc_proxy.py:306 [bob] --  ReceiveProxy binding port 8080, options: (('grpc.enable_retries', 1), ('grpc.so_reuseport', 0), ('grpc.max_send_message_length', 524288000), ('grpc.max_receive_message_length', 524288000), ('grpc.service_config', '{\"methodConfig\": [{\"name\": [{\"service\": \"GrpcService\"}], \"retryPolicy\": {\"maxAttempts\": 5, \"initialBackoff\": \"5s\", \"maxBackoff\": \"30s\", \"backoffMultiplier\": 2, \"retryableStatusCodes\": [\"UNAVAILABLE\"]}}]}'))...\n",
      "\u001b[2m\u001b[36m(ReceiverProxyActor pid=598)\u001b[0m 2023-10-10 05:18:23 INFO grpc_proxy.py:326 [bob] --  Successfully start Grpc service without credentials.\n",
      "2023-10-10 05:18:24 INFO barriers.py:283 [bob] --  SenderProxyActor has successfully created.\n",
      "2023-10-10 05:18:24 INFO barriers.py:438 [bob] --  Try ping ['alice'] at 0 attemp, up to 3600 attemps.\n"
     ]
    }
   ],
   "source": [
    "sf.shutdown()\n",
    "sf.init(\n",
    "    address='127.0.0.1:6379',\n",
    "    cluster_config={**network_conf, 'self_party': 'bob'},\n",
    "    log_to_driver=True,\n",
    ")"
   ]
  },
  {
   "cell_type": "markdown",
   "id": "a6da7bf4-0e7a-4a92-9a89-a54aa6ab31e2",
   "metadata": {},
   "source": [
    "## 初始化 SPU\n",
    "\n",
    "1. alice 的 address 请填写可以被 bob 访通的地址，并且选择一个**未被占用的端口** ，注意不要和 Ray 端口冲突。\n",
    "2. alice 的 listen_addr 可以和 alice address 里的端口一样。\n",
    "3. bob 的 address 请填写可以被 alice 访通的地址，并且选择一个**未被占用的端口** ，注意不要和 Ray 端口冲突。\n",
    "4. bob 的 listen_addr 可以和 bob address 里的端口一样。"
   ]
  },
  {
   "cell_type": "code",
   "execution_count": 3,
   "id": "4a3d7363-fc68-489d-afb1-3723010e5a01",
   "metadata": {
    "execution": {
     "executionParty": "[\"1e1e72d3-844e-4ada-966e-d56bb5f217ed\",\"806a79e5-f708-4e3e-a0ff-e3ea0503a00a\"]",
     "shell.execute_reply.end": "2023-10-10T05:18:24.569499Z",
     "shell.execute_reply.started": "2023-10-10T05:18:24.415938Z",
     "to_execute": "2023-10-10T05:18:20.667Z"
    }
   },
   "outputs": [],
   "source": [
    "alice, bob = sf.PYU('alice'), sf.PYU('bob')\n",
    "spu_conf = {\n",
    "    \"nodes\": [\n",
    "        {\n",
    "            \"party\": \"alice\",\n",
    "            \"address\": \"alice:8081\",\n",
    "            \"listen_addr\": \"alice:8081\"\n",
    "        },\n",
    "        {\n",
    "            \"party\": \"bob\",\n",
    "            \"address\": \"bob:8081\",\n",
    "            \"listen_addr\": \"alice:8081\"\n",
    "        },\n",
    "    ],\n",
    "    \"runtime_config\": {\n",
    "        \"protocol\": spu.spu_pb2.SEMI2K,\n",
    "        \"field\": spu.spu_pb2.FM128,\n",
    "        \"sigmoid_mode\": spu.spu_pb2.RuntimeConfig.SIGMOID_REAL,\n",
    "    },\n",
    "}\n",
    "spu = sf.SPU(cluster_def=spu_conf)"
   ]
  },
  {
   "cell_type": "markdown",
   "id": "fc12b191-abdb-43f6-86f3-06b06e13b3ba",
   "metadata": {},
   "source": [
    "## 隐私求交\n",
    "\n",
    "<span style=\"color: rgb(50, 50, 50)\">提供 </span>`psi_csv`<span style=\"color: rgb(50, 50, 50)\"> 函数， </span>`psi_csv`<span style=\"color: rgb(50, 50, 50)\"> 将 csv 文件作为输入，并在求交后生成 csv 文件。默认协议为 </span>[**KKRT**](https://eprint.iacr.org/2016/799.pdf)<span style=\"color: rgb(50, 50, 50)\">。</span>"
   ]
  },
  {
   "cell_type": "code",
   "execution_count": 4,
   "id": "293ad974-0904-4955-b1fa-8649331d40dd",
   "metadata": {
    "execution": {
     "executionParty": "[\"1e1e72d3-844e-4ada-966e-d56bb5f217ed\",\"806a79e5-f708-4e3e-a0ff-e3ea0503a00a\"]",
     "shell.execute_reply.end": "2023-10-10T05:18:28.255849Z",
     "shell.execute_reply.started": "2023-10-10T05:18:24.472542Z",
     "to_execute": "2023-10-10T05:18:20.667Z"
    }
   },
   "outputs": [
    {
     "data": {
      "text/html": [
       "<h4>Alice (You)'s Output:</h4>"
      ]
     },
     "metadata": {},
     "output_type": "display_data"
    },
    {
     "name": "stderr",
     "output_type": "stream",
     "text": [
      "2023-10-10 05:18:26,135\tWARNING worker.py:1851 -- Traceback (most recent call last):\n",
      "  File \"python/ray/_raylet.pyx\", line 823, in ray._raylet.execute_task\n",
      "  File \"python/ray/_raylet.pyx\", line 875, in ray._raylet.execute_task\n",
      "  File \"python/ray/_raylet.pyx\", line 830, in ray._raylet.execute_task\n",
      "  File \"python/ray/_raylet.pyx\", line 834, in ray._raylet.execute_task\n",
      "  File \"python/ray/_raylet.pyx\", line 780, in ray._raylet.execute_task.function_executor\n",
      "  File \"/usr/local/lib/python3.8/site-packages/ray/_private/function_manager.py\", line 674, in actor_method_executor\n",
      "    return method(__ray_actor, *args, **kwargs)\n",
      "  File \"/usr/local/lib/python3.8/site-packages/ray/util/tracing/tracing_helper.py\", line 466, in _resume_span\n",
      "    return method(self, *_args, **_kwargs)\n",
      "  File \"/usr/local/lib/python3.8/site-packages/secretflow/device/device/spu.py\", line 370, in __init__\n",
      "    self.link = spu_link.create_brpc(desc, rank)\n",
      "RuntimeError: what: \n",
      "\t[external/yacl/yacl/link/transport/brpc_link.cc:130] brpc server failed start\n",
      "Stacktrace:\n",
      "#0 yacl::link::FactoryBrpc::CreateContext()+0x7f5013ac5799\n",
      "#1 pybind11::cpp_function::initialize<>()::{lambda()#3}::_FUN()+0x7f50125ecad6\n",
      "#2 pybind11::cpp_function::dispatcher()+0x7f50125cf1c6\n",
      "#3 PyCFunction_Call+0x4e0212\n",
      "\n",
      "stacktrace: \n",
      "#0 yacl::link::FactoryBrpc::CreateContext()+0x7f5013ac5799\n",
      "#1 pybind11::cpp_function::initialize<>()::{lambda()#3}::_FUN()+0x7f50125ecad6\n",
      "#2 pybind11::cpp_function::dispatcher()+0x7f50125cf1c6\n",
      "#3 PyCFunction_Call+0x4e0212\n",
      "\n",
      "\n",
      "\n",
      "During handling of the above exception, another exception occurred:\n",
      "\n",
      "Traceback (most recent call last):\n",
      "  File \"python/ray/_raylet.pyx\", line 1135, in ray._raylet.task_execution_handler\n",
      "  File \"python/ray/_raylet.pyx\", line 1045, in ray._raylet.execute_task_with_cancellation_handler\n",
      "  File \"python/ray/_raylet.pyx\", line 782, in ray._raylet.execute_task\n",
      "  File \"python/ray/_raylet.pyx\", line 945, in ray._raylet.execute_task\n",
      "  File \"python/ray/_raylet.pyx\", line 575, in ray._raylet.store_task_errors\n",
      "  File \"/usr/local/lib/python3.8/site-packages/ray/util/tracing/tracing_helper.py\", line 466, in _resume_span\n",
      "    return method(self, *_args, **_kwargs)\n",
      "  File \"/usr/local/lib/python3.8/site-packages/secretflow/device/device/spu.py\", line 379, in __repr__\n",
      "    return f\"SPURuntime(device_id={self.id}, party={self.party})\"\n",
      "AttributeError: 'SPURuntime' object has no attribute 'id'\n",
      "An unexpected internal error occurred while the worker was executing a task.\n",
      "2023-10-10 05:18:26,139\tWARNING worker.py:1851 -- A worker died or was killed while executing a task by an unexpected system error. To troubleshoot the problem, check the logs for the dead worker. RayTask ID: ffffffffffffffff7b0a71680fdf55c835e15cbd02000000 Worker ID: 3e983cafece5f7ed736ea470a212e17301aa91a14273cf74277260cf Node ID: 83e3e86722f8dcfa88fcfa76345fdac10f8d431899b37b4e1ca6c4ce Worker IP address: 172.21.0.2 Worker port: 10009 Worker PID: 716 Worker exit type: SYSTEM_ERROR Worker exit detail: Worker exits unexpectedly. Worker exits with an exit code None.\n",
      " Traceback (most recent call last):\n",
      "  File \"python/ray/_raylet.pyx\", line 823, in ray._raylet.execute_task\n",
      "  File \"python/ray/_raylet.pyx\", line 875, in ray._raylet.execute_task\n",
      "  File \"python/ray/_raylet.pyx\", line 830, in ray._raylet.execute_task\n",
      "  File \"python/ray/_raylet.pyx\", line 834, in ray._raylet.execute_task\n",
      "  File \"python/ray/_raylet.pyx\", line 780, in ray._raylet.execute_task.function_executor\n",
      "  File \"/usr/local/lib/python3.8/site-packages/ray/_private/function_manager.py\", line 674, in actor_method_executor\n",
      "    return method(__ray_actor, *args, **kwargs)\n",
      "  File \"/usr/local/lib/python3.8/site-packages/ray/util/tracing/tracing_helper.py\", line 466, in _resume_span\n",
      "    return method(self, *_args, **_kwargs)\n",
      "  File \"/usr/local/lib/python3.8/site-packages/secretflow/device/device/spu.py\", line 370, in __init__\n",
      "    self.link = spu_link.create_brpc(desc, rank)\n",
      "RuntimeError: what: \n",
      "\t[external/yacl/yacl/link/transport/brpc_link.cc:130] brpc server failed start\n",
      "Stacktrace:\n",
      "#0 yacl::link::FactoryBrpc::CreateContext()+0x7f5013ac5799\n",
      "#1 pybind11::cpp_function::initialize<>()::{lambda()#3}::_FUN()+0x7f50125ecad6\n",
      "#2 pybind11::cpp_function::dispatcher()+0x7f50125cf1c6\n",
      "#3 PyCFunction_Call+0x4e0212\n",
      "\n",
      "stacktrace: \n",
      "#0 yacl::link::FactoryBrpc::CreateContext()+0x7f5013ac5799\n",
      "#1 pybind11::cpp_function::initialize<>()::{lambda()#3}::_FUN()+0x7f50125ecad6\n",
      "#2 pybind11::cpp_function::dispatcher()+0x7f50125cf1c6\n",
      "#3 PyCFunction_Call+0x4e0212\n",
      "\n",
      "\n",
      "\n",
      "During handling of the above exception, another exception occurred:\n",
      "\n",
      "Traceback (most recent call last):\n",
      "  File \"python/ray/_raylet.pyx\", line 1135, in ray._raylet.task_execution_handler\n",
      "  File \"python/ray/_raylet.pyx\", line 1045, in ray._raylet.execute_task_with_cancellation_handler\n",
      "  File \"python/ray/_raylet.pyx\", line 782, in ray._raylet.execute_task\n",
      "  File \"python/ray/_raylet.pyx\", line 945, in ray._raylet.execute_task\n",
      "  File \"python/ray/_raylet.pyx\", line 575, in ray._raylet.store_task_errors\n",
      "  File \"/usr/local/lib/python3.8/site-packages/ray/util/tracing/tracing_helper.py\", line 466, in _resume_span\n",
      "    return method(self, *_args, **_kwargs)\n",
      "  File \"/usr/local/lib/python3.8/site-packages/secretflow/device/device/spu.py\", line 379, in __repr__\n",
      "    return f\"SPURuntime(device_id={self.id}, party={self.party})\"\n",
      "AttributeError: 'SPURuntime' object has no attribute 'id'\n",
      "An unexpected internal error occurred while the worker was executing a task.\n",
      "2023-10-10 05:18:26 WARNING cleanup.py:99 [alice] --  Failed to send ObjectRef(0d12401e8fa9a714c8e08e9be09efa78b6a95cb50200000001000000) with error: \u001b[36mray::SenderProxyActor.send()\u001b[39m (pid=671, ip=172.21.0.2, repr=<fed.proxy.barriers.SenderProxyActor object at 0x7f112c15a250>)\n",
      "  At least one of the input arguments for this task could not be computed:\n",
      "ray.exceptions.RayActorError: The actor died unexpectedly before finishing this task.\n",
      "\tclass_name: SPURuntime\n",
      "\tactor_id: 7b0a71680fdf55c835e15cbd02000000\n",
      "\tpid: 716\n",
      "\tnamespace: 36f67683-355f-43b8-8ac5-b0d3b29372ae\n",
      "\tip: 172.21.0.2\n",
      "The actor is dead because its worker process has died. Worker exit type: SYSTEM_ERROR Worker exit detail: Worker exits unexpectedly. Worker exits with an exit code None.\n",
      " Traceback (most recent call last):\n",
      "  File \"/usr/local/lib/python3.8/site-packages/secretflow/device/device/spu.py\", line 370, in __init__\n",
      "    self.link = spu_link.create_brpc(desc, rank)\n",
      "RuntimeError: what: \n",
      "\t[external/yacl/yacl/link/transport/brpc_link.cc:130] brpc server failed start\n",
      "Stacktrace:\n",
      "#0 yacl::link::FactoryBrpc::CreateContext()+0x7f5013ac5799\n",
      "#1 pybind11::cpp_function::initialize<>()::{lambda()#3}::_FUN()+0x7f50125ecad6\n",
      "#2 pybind11::cpp_function::dispatcher()+0x7f50125cf1c6\n",
      "#3 PyCFunction_Call+0x4e0212\n",
      "\n",
      "stacktrace: \n",
      "#0 yacl::link::FactoryBrpc::CreateContext()+0x7f5013ac5799\n",
      "#1 pybind11::cpp_function::initialize<>()::{lambda()#3}::_FUN()+0x7f50125ecad6\n",
      "#2 pybind11::cpp_function::dispatcher()+0x7f50125cf1c6\n",
      "#3 PyCFunction_Call+0x4e0212\n",
      "\n",
      "\n",
      "\n",
      "During handling of the above exception, another exception occurred:\n",
      "\n",
      "\u001b[36mray::SenderProxyActor.send()\u001b[39m (pid=671, ip=172.21.0.2, repr=<fed.proxy.barriers.SenderProxyActor object at 0x7f112c15a250>)\n",
      "  File \"/usr/local/lib/python3.8/site-packages/secretflow/device/device/spu.py\", line 379, in __repr__\n",
      "    return f\"SPURuntime(device_id={self.id}, party={self.party})\"\n",
      "AttributeError: 'SPURuntime' object has no attribute 'id'\n",
      "An unexpected internal error occurred while the worker was executing a task.\n",
      "2023-10-10 05:18:26 WARNING cleanup.py:102 [alice] --  Signal self to exit.\n",
      "2023-10-10 05:18:26 INFO cleanup.py:106 [alice] --  Check sending thread was exited.\n",
      "*** SIGTERM received at time=1696915106 on cpu 5 ***\n",
      "PC: @     0x7fd8f860e848  (unknown)  pthread_cond_timedwait@@GLIBC_2.3.2\n",
      "    @     0x7fd8f8612cf0  (unknown)  (unknown)\n",
      "[2023-10-10 05:18:26,158 E 541 541] logging.cc:361: *** SIGTERM received at time=1696915106 on cpu 5 ***\n",
      "[2023-10-10 05:18:26,158 E 541 541] logging.cc:361: PC: @     0x7fd8f860e848  (unknown)  pthread_cond_timedwait@@GLIBC_2.3.2\n",
      "[2023-10-10 05:18:26,158 E 541 541] logging.cc:361:     @     0x7fd8f8612cf0  (unknown)  (unknown)\n",
      "\u001b[2m\u001b[36m(SPURuntime pid=716)\u001b[0m 2023-10-10 05:18:26,134\tERROR worker.py:763 -- Worker exits with an exit code None.\n",
      "\u001b[2m\u001b[36m(SPURuntime pid=716)\u001b[0m  Traceback (most recent call last):\n",
      "\u001b[2m\u001b[36m(SPURuntime pid=716)\u001b[0m   File \"python/ray/_raylet.pyx\", line 823, in ray._raylet.execute_task\n",
      "\u001b[2m\u001b[36m(SPURuntime pid=716)\u001b[0m   File \"python/ray/_raylet.pyx\", line 875, in ray._raylet.execute_task\n",
      "\u001b[2m\u001b[36m(SPURuntime pid=716)\u001b[0m   File \"python/ray/_raylet.pyx\", line 830, in ray._raylet.execute_task\n",
      "\u001b[2m\u001b[36m(SPURuntime pid=716)\u001b[0m   File \"python/ray/_raylet.pyx\", line 834, in ray._raylet.execute_task\n",
      "\u001b[2m\u001b[36m(SPURuntime pid=716)\u001b[0m   File \"python/ray/_raylet.pyx\", line 780, in ray._raylet.execute_task.function_executor\n",
      "\u001b[2m\u001b[36m(SPURuntime pid=716)\u001b[0m   File \"/usr/local/lib/python3.8/site-packages/ray/_private/function_manager.py\", line 674, in actor_method_executor\n",
      "\u001b[2m\u001b[36m(SPURuntime pid=716)\u001b[0m     return method(__ray_actor, *args, **kwargs)\n",
      "\u001b[2m\u001b[36m(SPURuntime pid=716)\u001b[0m   File \"/usr/local/lib/python3.8/site-packages/ray/util/tracing/tracing_helper.py\", line 466, in _resume_span\n",
      "\u001b[2m\u001b[36m(SPURuntime pid=716)\u001b[0m     return method(self, *_args, **_kwargs)\n",
      "\u001b[2m\u001b[36m(SPURuntime pid=716)\u001b[0m   File \"/usr/local/lib/python3.8/site-packages/secretflow/device/device/spu.py\", line 370, in __init__\n",
      "\u001b[2m\u001b[36m(SPURuntime pid=716)\u001b[0m     self.link = spu_link.create_brpc(desc, rank)\n",
      "\u001b[2m\u001b[36m(SPURuntime pid=716)\u001b[0m RuntimeError: what: \n",
      "\u001b[2m\u001b[36m(SPURuntime pid=716)\u001b[0m \t[external/yacl/yacl/link/transport/brpc_link.cc:130] brpc server failed start\n",
      "\u001b[2m\u001b[36m(SPURuntime pid=716)\u001b[0m Stacktrace:\n",
      "\u001b[2m\u001b[36m(SPURuntime pid=716)\u001b[0m #0 yacl::link::FactoryBrpc::CreateContext()+0x7f5013ac5799\n",
      "\u001b[2m\u001b[36m(SPURuntime pid=716)\u001b[0m #1 pybind11::cpp_function::initialize<>()::{lambda()#3}::_FUN()+0x7f50125ecad6\n",
      "\u001b[2m\u001b[36m(SPURuntime pid=716)\u001b[0m #2 pybind11::cpp_function::dispatcher()+0x7f50125cf1c6\n",
      "\u001b[2m\u001b[36m(SPURuntime pid=716)\u001b[0m #3 PyCFunction_Call+0x4e0212\n",
      "\u001b[2m\u001b[36m(SPURuntime pid=716)\u001b[0m \n",
      "\u001b[2m\u001b[36m(SPURuntime pid=716)\u001b[0m stacktrace: \n",
      "\u001b[2m\u001b[36m(SPURuntime pid=716)\u001b[0m #0 yacl::link::FactoryBrpc::CreateContext()+0x7f5013ac5799\n",
      "\u001b[2m\u001b[36m(SPURuntime pid=716)\u001b[0m #1 pybind11::cpp_function::initialize<>()::{lambda()#3}::_FUN()+0x7f50125ecad6\n",
      "\u001b[2m\u001b[36m(SPURuntime pid=716)\u001b[0m #2 pybind11::cpp_function::dispatcher()+0x7f50125cf1c6\n",
      "\u001b[2m\u001b[36m(SPURuntime pid=716)\u001b[0m #3 PyCFunction_Call+0x4e0212\n",
      "\u001b[2m\u001b[36m(SPURuntime pid=716)\u001b[0m \n",
      "\u001b[2m\u001b[36m(SPURuntime pid=716)\u001b[0m \n",
      "\u001b[2m\u001b[36m(SPURuntime pid=716)\u001b[0m \n",
      "\u001b[2m\u001b[36m(SPURuntime pid=716)\u001b[0m During handling of the above exception, another exception occurred:\n",
      "\u001b[2m\u001b[36m(SPURuntime pid=716)\u001b[0m \n",
      "\u001b[2m\u001b[36m(SPURuntime pid=716)\u001b[0m Traceback (most recent call last):\n",
      "\u001b[2m\u001b[36m(SPURuntime pid=716)\u001b[0m   File \"python/ray/_raylet.pyx\", line 1135, in ray._raylet.task_execution_handler\n",
      "\u001b[2m\u001b[36m(SPURuntime pid=716)\u001b[0m   File \"python/ray/_raylet.pyx\", line 1045, in ray._raylet.execute_task_with_cancellation_handler\n",
      "\u001b[2m\u001b[36m(SPURuntime pid=716)\u001b[0m   File \"python/ray/_raylet.pyx\", line 782, in ray._raylet.execute_task\n",
      "\u001b[2m\u001b[36m(SPURuntime pid=716)\u001b[0m   File \"python/ray/_raylet.pyx\", line 945, in ray._raylet.execute_task\n",
      "\u001b[2m\u001b[36m(SPURuntime pid=716)\u001b[0m   File \"python/ray/_raylet.pyx\", line 575, in ray._raylet.store_task_errors\n",
      "\u001b[2m\u001b[36m(SPURuntime pid=716)\u001b[0m   File \"/usr/local/lib/python3.8/site-packages/ray/util/tracing/tracing_helper.py\", line 466, in _resume_span\n",
      "\u001b[2m\u001b[36m(SPURuntime pid=716)\u001b[0m     return method(self, *_args, **_kwargs)\n",
      "\u001b[2m\u001b[36m(SPURuntime pid=716)\u001b[0m   File \"/usr/local/lib/python3.8/site-packages/secretflow/device/device/spu.py\", line 379, in __repr__\n",
      "\u001b[2m\u001b[36m(SPURuntime pid=716)\u001b[0m     return f\"SPURuntime(device_id={self.id}, party={self.party})\"\n",
      "\u001b[2m\u001b[36m(SPURuntime pid=716)\u001b[0m AttributeError: 'SPURuntime' object has no attribute 'id'\n",
      "\u001b[2m\u001b[36m(SPURuntime pid=716)\u001b[0m An unexpected internal error occurred while the worker was executing a task.\n",
      "\u001b[2m\u001b[36m(SPURuntime pid=716)\u001b[0m Traceback (most recent call last):\n",
      "\u001b[2m\u001b[36m(SPURuntime pid=716)\u001b[0m   File \"python/ray/_raylet.pyx\", line 823, in ray._raylet.execute_task\n",
      "\u001b[2m\u001b[36m(SPURuntime pid=716)\u001b[0m   File \"python/ray/_raylet.pyx\", line 875, in ray._raylet.execute_task\n",
      "\u001b[2m\u001b[36m(SPURuntime pid=716)\u001b[0m   File \"python/ray/_raylet.pyx\", line 830, in ray._raylet.execute_task\n",
      "\u001b[2m\u001b[36m(SPURuntime pid=716)\u001b[0m   File \"python/ray/_raylet.pyx\", line 834, in ray._raylet.execute_task\n",
      "\u001b[2m\u001b[36m(SPURuntime pid=716)\u001b[0m   File \"python/ray/_raylet.pyx\", line 780, in ray._raylet.execute_task.function_executor\n",
      "\u001b[2m\u001b[36m(SPURuntime pid=716)\u001b[0m   File \"/usr/local/lib/python3.8/site-packages/ray/_private/function_manager.py\", line 674, in actor_method_executor\n",
      "\u001b[2m\u001b[36m(SPURuntime pid=716)\u001b[0m     return method(__ray_actor, *args, **kwargs)\n",
      "\u001b[2m\u001b[36m(SPURuntime pid=716)\u001b[0m   File \"/usr/local/lib/python3.8/site-packages/ray/util/tracing/tracing_helper.py\", line 466, in _resume_span\n",
      "\u001b[2m\u001b[36m(SPURuntime pid=716)\u001b[0m     return method(self, *_args, **_kwargs)\n",
      "\u001b[2m\u001b[36m(SPURuntime pid=716)\u001b[0m   File \"/usr/local/lib/python3.8/site-packages/secretflow/device/device/spu.py\", line 370, in __init__\n",
      "\u001b[2m\u001b[36m(SPURuntime pid=716)\u001b[0m     self.link = spu_link.create_brpc(desc, rank)\n",
      "\u001b[2m\u001b[36m(SPURuntime pid=716)\u001b[0m RuntimeError: what: \n",
      "\u001b[2m\u001b[36m(SPURuntime pid=716)\u001b[0m \t[external/yacl/yacl/link/transport/brpc_link.cc:130] brpc server failed start\n",
      "\u001b[2m\u001b[36m(SPURuntime pid=716)\u001b[0m Stacktrace:\n",
      "\u001b[2m\u001b[36m(SPURuntime pid=716)\u001b[0m #0 yacl::link::FactoryBrpc::CreateContext()+0x7f5013ac5799\n",
      "\u001b[2m\u001b[36m(SPURuntime pid=716)\u001b[0m #1 pybind11::cpp_function::initialize<>()::{lambda()#3}::_FUN()+0x7f50125ecad6\n",
      "\u001b[2m\u001b[36m(SPURuntime pid=716)\u001b[0m #2 pybind11::cpp_function::dispatcher()+0x7f50125cf1c6\n",
      "\u001b[2m\u001b[36m(SPURuntime pid=716)\u001b[0m #3 PyCFunction_Call+0x4e0212\n",
      "\u001b[2m\u001b[36m(SPURuntime pid=716)\u001b[0m \n",
      "\u001b[2m\u001b[36m(SPURuntime pid=716)\u001b[0m stacktrace: \n",
      "\u001b[2m\u001b[36m(SPURuntime pid=716)\u001b[0m #0 yacl::link::FactoryBrpc::CreateContext()+0x7f5013ac5799\n",
      "\u001b[2m\u001b[36m(SPURuntime pid=716)\u001b[0m #1 pybind11::cpp_function::initialize<>()::{lambda()#3}::_FUN()+0x7f50125ecad6\n",
      "\u001b[2m\u001b[36m(SPURuntime pid=716)\u001b[0m #2 pybind11::cpp_function::dispatcher()+0x7f50125cf1c6\n",
      "\u001b[2m\u001b[36m(SPURuntime pid=716)\u001b[0m #3 PyCFunction_Call+0x4e0212\n",
      "\u001b[2m\u001b[36m(SPURuntime pid=716)\u001b[0m \n",
      "\u001b[2m\u001b[36m(SPURuntime pid=716)\u001b[0m \n",
      "\u001b[2m\u001b[36m(SPURuntime pid=716)\u001b[0m \n",
      "\u001b[2m\u001b[36m(SPURuntime pid=716)\u001b[0m During handling of the above exception, another exception occurred:\n",
      "\u001b[2m\u001b[36m(SPURuntime pid=716)\u001b[0m \n",
      "\u001b[2m\u001b[36m(SPURuntime pid=716)\u001b[0m Traceback (most recent call last):\n",
      "\u001b[2m\u001b[36m(SPURuntime pid=716)\u001b[0m   File \"python/ray/_raylet.pyx\", line 1135, in ray._raylet.task_execution_handler\n",
      "\u001b[2m\u001b[36m(SPURuntime pid=716)\u001b[0m   File \"python/ray/_raylet.pyx\", line 1045, in ray._raylet.execute_task_with_cancellation_handler\n",
      "\u001b[2m\u001b[36m(SPURuntime pid=716)\u001b[0m   File \"python/ray/_raylet.pyx\", line 782, in ray._raylet.execute_task\n",
      "\u001b[2m\u001b[36m(SPURuntime pid=716)\u001b[0m   File \"python/ray/_raylet.pyx\", line 945, in ray._raylet.execute_task\n",
      "\u001b[2m\u001b[36m(SPURuntime pid=716)\u001b[0m   File \"python/ray/_raylet.pyx\", line 575, in ray._raylet.store_task_errors\n",
      "\u001b[2m\u001b[36m(SPURuntime pid=716)\u001b[0m   File \"/usr/local/lib/python3.8/site-packages/ray/util/tracing/tracing_helper.py\", line 466, in _resume_span\n",
      "\u001b[2m\u001b[36m(SPURuntime pid=716)\u001b[0m     return method(self, *_args, **_kwargs)\n",
      "\u001b[2m\u001b[36m(SPURuntime pid=716)\u001b[0m   File \"/usr/local/lib/python3.8/site-packages/secretflow/device/device/spu.py\", line 379, in __repr__\n",
      "\u001b[2m\u001b[36m(SPURuntime pid=716)\u001b[0m     return f\"SPURuntime(device_id={self.id}, party={self.party})\"\n",
      "\u001b[2m\u001b[36m(SPURuntime pid=716)\u001b[0m AttributeError: 'SPURuntime' object has no attribute 'id'\n",
      "\u001b[2m\u001b[36m(SPURuntime pid=716)\u001b[0m \n",
      "\u001b[2m\u001b[36m(SPURuntime pid=716)\u001b[0m During handling of the above exception, another exception occurred:\n",
      "\u001b[2m\u001b[36m(SPURuntime pid=716)\u001b[0m \n",
      "\u001b[2m\u001b[36m(SPURuntime pid=716)\u001b[0m Traceback (most recent call last):\n",
      "\u001b[2m\u001b[36m(SPURuntime pid=716)\u001b[0m   File \"python/ray/_raylet.pyx\", line 1176, in ray._raylet.task_execution_handler\n",
      "\u001b[2m\u001b[36m(SPURuntime pid=716)\u001b[0m SystemExit\n"
     ]
    },
    {
     "name": "stdout",
     "output_type": "stream",
     "text": [
      "\u001b[2m\u001b[36m(SPURuntime pid=716)\u001b[0m 2023-10-10 05:18:26.119 [error] [server.cpp:BRPC:1023] Fail to listen 172.21.0.3:8081\n",
      "\u001b[2m\u001b[36m(SPURuntime pid=716)\u001b[0m 2023-10-10 05:18:26.132 [warning] [channel.h:~Channel:151] Channel destructor is called before WaitLinkTaskFinish, try stop send thread\n"
     ]
    },
    {
     "ename": "SystemExit",
     "evalue": "15",
     "output_type": "error",
     "traceback": [
      "\u001b[0;31m---------------------------------------------------------------------------\u001b[0m",
      "\u001b[0;31mRayActorError\u001b[0m                             Traceback (most recent call last)",
      "    \u001b[0;31m[... skipping hidden 1 frame]\u001b[0m\n",
      "Cell \u001b[0;32mIn[4], line 7\u001b[0m\n\u001b[1;32m      6\u001b[0m output_path \u001b[38;5;241m=\u001b[39m {alice: \u001b[38;5;124mf\u001b[39m\u001b[38;5;124m'\u001b[39m\u001b[38;5;132;01m{\u001b[39;00mcurrent_dir\u001b[38;5;132;01m}\u001b[39;00m\u001b[38;5;124m/iris_alice_psi.csv\u001b[39m\u001b[38;5;124m'\u001b[39m, bob: \u001b[38;5;124mf\u001b[39m\u001b[38;5;124m'\u001b[39m\u001b[38;5;132;01m{\u001b[39;00mcurrent_dir\u001b[38;5;132;01m}\u001b[39;00m\u001b[38;5;124m/iris_alice_psi.csv\u001b[39m\u001b[38;5;124m'\u001b[39m}\n\u001b[0;32m----> 7\u001b[0m \u001b[43mspu\u001b[49m\u001b[38;5;241;43m.\u001b[39;49m\u001b[43mpsi_csv\u001b[49m\u001b[43m(\u001b[49m\u001b[38;5;124;43m'\u001b[39;49m\u001b[38;5;124;43muid\u001b[39;49m\u001b[38;5;124;43m'\u001b[39;49m\u001b[43m,\u001b[49m\u001b[43m \u001b[49m\u001b[43minput_path\u001b[49m\u001b[43m,\u001b[49m\u001b[43m \u001b[49m\u001b[43moutput_path\u001b[49m\u001b[43m,\u001b[49m\u001b[43m \u001b[49m\u001b[38;5;124;43m'\u001b[39;49m\u001b[38;5;124;43malice\u001b[39;49m\u001b[38;5;124;43m'\u001b[39;49m\u001b[43m)\u001b[49m\n",
      "File \u001b[0;32m/usr/local/lib/python3.8/site-packages/secretflow/device/device/spu.py:1978\u001b[0m, in \u001b[0;36mSPU.psi_csv\u001b[0;34m(self, key, input_path, output_path, receiver, protocol, precheck_input, sort, broadcast_result, bucket_size, curve_type, preprocess_path, ecdh_secret_key_path, dppsi_bob_sub_sampling, dppsi_epsilon, progress_callbacks, callbacks_interval_ms)\u001b[0m\n\u001b[1;32m   1948\u001b[0m \u001b[38;5;250m\u001b[39m\u001b[38;5;124;03m\"\"\"Private set intersection with csv file.\u001b[39;00m\n\u001b[1;32m   1949\u001b[0m \n\u001b[1;32m   1950\u001b[0m \u001b[38;5;124;03mArgs:\u001b[39;00m\n\u001b[0;32m   (...)\u001b[0m\n\u001b[1;32m   1975\u001b[0m \u001b[38;5;124;03m    List[Dict]: PSI reports output by SPU with order reserved.\u001b[39;00m\n\u001b[1;32m   1976\u001b[0m \u001b[38;5;124;03m\"\"\"\u001b[39;00m\n\u001b[0;32m-> 1978\u001b[0m \u001b[38;5;28;01mreturn\u001b[39;00m \u001b[43mdispatch\u001b[49m\u001b[43m(\u001b[49m\n\u001b[1;32m   1979\u001b[0m \u001b[43m    \u001b[49m\u001b[38;5;124;43m'\u001b[39;49m\u001b[38;5;124;43mpsi_csv\u001b[39;49m\u001b[38;5;124;43m'\u001b[39;49m\u001b[43m,\u001b[49m\n\u001b[1;32m   1980\u001b[0m \u001b[43m    \u001b[49m\u001b[38;5;28;43mself\u001b[39;49m\u001b[43m,\u001b[49m\n\u001b[1;32m   1981\u001b[0m \u001b[43m    \u001b[49m\u001b[43mkey\u001b[49m\u001b[43m,\u001b[49m\n\u001b[1;32m   1982\u001b[0m \u001b[43m    \u001b[49m\u001b[43minput_path\u001b[49m\u001b[43m,\u001b[49m\n\u001b[1;32m   1983\u001b[0m \u001b[43m    \u001b[49m\u001b[43moutput_path\u001b[49m\u001b[43m,\u001b[49m\n\u001b[1;32m   1984\u001b[0m \u001b[43m    \u001b[49m\u001b[43mreceiver\u001b[49m\u001b[43m,\u001b[49m\n\u001b[1;32m   1985\u001b[0m \u001b[43m    \u001b[49m\u001b[43mprotocol\u001b[49m\u001b[43m,\u001b[49m\n\u001b[1;32m   1986\u001b[0m \u001b[43m    \u001b[49m\u001b[43mprecheck_input\u001b[49m\u001b[43m,\u001b[49m\n\u001b[1;32m   1987\u001b[0m \u001b[43m    \u001b[49m\u001b[43msort\u001b[49m\u001b[43m,\u001b[49m\n\u001b[1;32m   1988\u001b[0m \u001b[43m    \u001b[49m\u001b[43mbroadcast_result\u001b[49m\u001b[43m,\u001b[49m\n\u001b[1;32m   1989\u001b[0m \u001b[43m    \u001b[49m\u001b[43mbucket_size\u001b[49m\u001b[43m,\u001b[49m\n\u001b[1;32m   1990\u001b[0m \u001b[43m    \u001b[49m\u001b[43mcurve_type\u001b[49m\u001b[43m,\u001b[49m\n\u001b[1;32m   1991\u001b[0m \u001b[43m    \u001b[49m\u001b[43mpreprocess_path\u001b[49m\u001b[43m,\u001b[49m\n\u001b[1;32m   1992\u001b[0m \u001b[43m    \u001b[49m\u001b[43mecdh_secret_key_path\u001b[49m\u001b[43m,\u001b[49m\n\u001b[1;32m   1993\u001b[0m \u001b[43m    \u001b[49m\u001b[43mdppsi_bob_sub_sampling\u001b[49m\u001b[43m,\u001b[49m\n\u001b[1;32m   1994\u001b[0m \u001b[43m    \u001b[49m\u001b[43mdppsi_epsilon\u001b[49m\u001b[43m,\u001b[49m\n\u001b[1;32m   1995\u001b[0m \u001b[43m    \u001b[49m\u001b[43mprogress_callbacks\u001b[49m\u001b[43m,\u001b[49m\n\u001b[1;32m   1996\u001b[0m \u001b[43m    \u001b[49m\u001b[43mcallbacks_interval_ms\u001b[49m\u001b[43m,\u001b[49m\n\u001b[1;32m   1997\u001b[0m \u001b[43m\u001b[49m\u001b[43m)\u001b[49m\n",
      "File \u001b[0;32m/usr/local/lib/python3.8/site-packages/secretflow/device/device/register.py:111\u001b[0m, in \u001b[0;36mdispatch\u001b[0;34m(name, self, *args, **kwargs)\u001b[0m\n\u001b[1;32m    102\u001b[0m \u001b[38;5;250m\u001b[39m\u001b[38;5;124;03m\"\"\"Dispatch device kernel.\u001b[39;00m\n\u001b[1;32m    103\u001b[0m \n\u001b[1;32m    104\u001b[0m \u001b[38;5;124;03mArgs:\u001b[39;00m\n\u001b[0;32m   (...)\u001b[0m\n\u001b[1;32m    109\u001b[0m \u001b[38;5;124;03m    Kernel execution result.\u001b[39;00m\n\u001b[1;32m    110\u001b[0m \u001b[38;5;124;03m\"\"\"\u001b[39;00m\n\u001b[0;32m--> 111\u001b[0m \u001b[38;5;28;01mreturn\u001b[39;00m \u001b[43m_registrar\u001b[49m\u001b[38;5;241;43m.\u001b[39;49m\u001b[43mdispatch\u001b[49m\u001b[43m(\u001b[49m\u001b[38;5;28;43mself\u001b[39;49m\u001b[38;5;241;43m.\u001b[39;49m\u001b[43mdevice_type\u001b[49m\u001b[43m,\u001b[49m\u001b[43m \u001b[49m\u001b[43mname\u001b[49m\u001b[43m,\u001b[49m\u001b[43m \u001b[49m\u001b[38;5;28;43mself\u001b[39;49m\u001b[43m,\u001b[49m\u001b[43m \u001b[49m\u001b[38;5;241;43m*\u001b[39;49m\u001b[43margs\u001b[49m\u001b[43m,\u001b[49m\u001b[43m \u001b[49m\u001b[38;5;241;43m*\u001b[39;49m\u001b[38;5;241;43m*\u001b[39;49m\u001b[43mkwargs\u001b[49m\u001b[43m)\u001b[49m\n",
      "File \u001b[0;32m/usr/local/lib/python3.8/site-packages/secretflow/device/device/register.py:80\u001b[0m, in \u001b[0;36mRegistrar.dispatch\u001b[0;34m(self, device_type, name, *args, **kwargs)\u001b[0m\n\u001b[1;32m     79\u001b[0m     \u001b[38;5;28;01mraise\u001b[39;00m \u001b[38;5;167;01mKeyError\u001b[39;00m(\u001b[38;5;124mf\u001b[39m\u001b[38;5;124m'\u001b[39m\u001b[38;5;124mdevice: \u001b[39m\u001b[38;5;132;01m{\u001b[39;00mdevice_type\u001b[38;5;132;01m}\u001b[39;00m\u001b[38;5;124m, op: \u001b[39m\u001b[38;5;132;01m{\u001b[39;00mname\u001b[38;5;132;01m}\u001b[39;00m\u001b[38;5;124m not registered\u001b[39m\u001b[38;5;124m'\u001b[39m)\n\u001b[0;32m---> 80\u001b[0m \u001b[38;5;28;01mreturn\u001b[39;00m \u001b[38;5;28;43mself\u001b[39;49m\u001b[38;5;241;43m.\u001b[39;49m\u001b[43m_ops\u001b[49m\u001b[43m[\u001b[49m\u001b[43mdevice_type\u001b[49m\u001b[43m]\u001b[49m\u001b[43m[\u001b[49m\u001b[43mname\u001b[49m\u001b[43m]\u001b[49m\u001b[43m(\u001b[49m\u001b[38;5;241;43m*\u001b[39;49m\u001b[43margs\u001b[49m\u001b[43m,\u001b[49m\u001b[43m \u001b[49m\u001b[38;5;241;43m*\u001b[39;49m\u001b[38;5;241;43m*\u001b[39;49m\u001b[43mkwargs\u001b[49m\u001b[43m)\u001b[49m\n",
      "File \u001b[0;32m/usr/local/lib/python3.8/site-packages/secretflow/device/kernels/spu.py:318\u001b[0m, in \u001b[0;36mpsi_csv\u001b[0;34m(device, key, input_path, output_path, receiver, protocol, precheck_input, sort, broadcast_result, bucket_size, curve_type, preprocess_path, ecdh_secret_key_path, dppsi_bob_sub_sampling, dppsi_epsilon, progress_callbacks, callbacks_interval_ms)\u001b[0m\n\u001b[1;32m    317\u001b[0m \u001b[38;5;66;03m# wait for all tasks done\u001b[39;00m\n\u001b[0;32m--> 318\u001b[0m \u001b[38;5;28;01mreturn\u001b[39;00m \u001b[43msfd\u001b[49m\u001b[38;5;241;43m.\u001b[39;49m\u001b[43mget\u001b[49m\u001b[43m(\u001b[49m\u001b[43mres\u001b[49m\u001b[43m)\u001b[49m\n",
      "File \u001b[0;32m/usr/local/lib/python3.8/site-packages/secretflow/distributed/primitive.py:73\u001b[0m, in \u001b[0;36mget\u001b[0;34m(object_refs)\u001b[0m\n\u001b[1;32m     72\u001b[0m \u001b[38;5;28;01mif\u001b[39;00m production_mode():\n\u001b[0;32m---> 73\u001b[0m     \u001b[38;5;28;01mreturn\u001b[39;00m \u001b[43mfed\u001b[49m\u001b[38;5;241;43m.\u001b[39;49m\u001b[43mget\u001b[49m\u001b[43m(\u001b[49m\u001b[43mobject_refs\u001b[49m\u001b[43m)\u001b[49m\n\u001b[1;32m     74\u001b[0m \u001b[38;5;28;01melse\u001b[39;00m:\n",
      "File \u001b[0;32m/usr/local/lib/python3.8/site-packages/fed/api.py:395\u001b[0m, in \u001b[0;36mget\u001b[0;34m(fed_objects)\u001b[0m\n\u001b[1;32m    393\u001b[0m         ray_refs\u001b[38;5;241m.\u001b[39mappend(received_ray_object_ref)\n\u001b[0;32m--> 395\u001b[0m values \u001b[38;5;241m=\u001b[39m \u001b[43mray\u001b[49m\u001b[38;5;241;43m.\u001b[39;49m\u001b[43mget\u001b[49m\u001b[43m(\u001b[49m\u001b[43mray_refs\u001b[49m\u001b[43m)\u001b[49m\n\u001b[1;32m    396\u001b[0m \u001b[38;5;28;01mif\u001b[39;00m is_individual_id:\n",
      "File \u001b[0;32m/usr/local/lib/python3.8/site-packages/ray/_private/client_mode_hook.py:105\u001b[0m, in \u001b[0;36mclient_mode_hook.<locals>.wrapper\u001b[0;34m(*args, **kwargs)\u001b[0m\n\u001b[1;32m    104\u001b[0m         \u001b[38;5;28;01mreturn\u001b[39;00m \u001b[38;5;28mgetattr\u001b[39m(ray, func\u001b[38;5;241m.\u001b[39m\u001b[38;5;18m__name__\u001b[39m)(\u001b[38;5;241m*\u001b[39margs, \u001b[38;5;241m*\u001b[39m\u001b[38;5;241m*\u001b[39mkwargs)\n\u001b[0;32m--> 105\u001b[0m \u001b[38;5;28;01mreturn\u001b[39;00m \u001b[43mfunc\u001b[49m\u001b[43m(\u001b[49m\u001b[38;5;241;43m*\u001b[39;49m\u001b[43margs\u001b[49m\u001b[43m,\u001b[49m\u001b[43m \u001b[49m\u001b[38;5;241;43m*\u001b[39;49m\u001b[38;5;241;43m*\u001b[39;49m\u001b[43mkwargs\u001b[49m\u001b[43m)\u001b[49m\n",
      "File \u001b[0;32m/usr/local/lib/python3.8/site-packages/ray/_private/worker.py:2311\u001b[0m, in \u001b[0;36mget\u001b[0;34m(object_refs, timeout)\u001b[0m\n\u001b[1;32m   2310\u001b[0m         \u001b[38;5;28;01melse\u001b[39;00m:\n\u001b[0;32m-> 2311\u001b[0m             \u001b[38;5;28;01mraise\u001b[39;00m value\n\u001b[1;32m   2313\u001b[0m \u001b[38;5;28;01mif\u001b[39;00m is_individual_id:\n",
      "\u001b[0;31mRayActorError\u001b[0m: The actor died unexpectedly before finishing this task.\n\tclass_name: SPURuntime\n\tactor_id: 7b0a71680fdf55c835e15cbd02000000\n\tpid: 716\n\tnamespace: 36f67683-355f-43b8-8ac5-b0d3b29372ae\n\tip: 172.21.0.2\nThe actor is dead because its worker process has died. Worker exit type: SYSTEM_ERROR Worker exit detail: Worker exits unexpectedly. Worker exits with an exit code None.\n Traceback (most recent call last):\n  File \"python/ray/_raylet.pyx\", line 823, in ray._raylet.execute_task\n  File \"python/ray/_raylet.pyx\", line 875, in ray._raylet.execute_task\n  File \"python/ray/_raylet.pyx\", line 830, in ray._raylet.execute_task\n  File \"python/ray/_raylet.pyx\", line 834, in ray._raylet.execute_task\n  File \"python/ray/_raylet.pyx\", line 780, in ray._raylet.execute_task.function_executor\n  File \"/usr/local/lib/python3.8/site-packages/ray/_private/function_manager.py\", line 674, in actor_method_executor\n    return method(__ray_actor, *args, **kwargs)\n  File \"/usr/local/lib/python3.8/site-packages/ray/util/tracing/tracing_helper.py\", line 466, in _resume_span\n    return method(self, *_args, **_kwargs)\n  File \"/usr/local/lib/python3.8/site-packages/secretflow/device/device/spu.py\", line 370, in __init__\n    self.link = spu_link.create_brpc(desc, rank)\nRuntimeError: what: \n\t[external/yacl/yacl/link/transport/brpc_link.cc:130] brpc server failed start\nStacktrace:\n#0 yacl::link::FactoryBrpc::CreateContext()+0x7f5013ac5799\n#1 pybind11::cpp_function::initialize<>()::{lambda()#3}::_FUN()+0x7f50125ecad6\n#2 pybind11::cpp_function::dispatcher()+0x7f50125cf1c6\n#3 PyCFunction_Call+0x4e0212\n\nstacktrace: \n#0 yacl::link::FactoryBrpc::CreateContext()+0x7f5013ac5799\n#1 pybind11::cpp_function::initialize<>()::{lambda()#3}::_FUN()+0x7f50125ecad6\n#2 pybind11::cpp_function::dispatcher()+0x7f50125cf1c6\n#3 PyCFunction_Call+0x4e0212\n\n\n\nDuring handling of the above exception, another exception occurred:\n\nTraceback (most recent call last):\n  File \"python/ray/_raylet.pyx\", line 1135, in ray._raylet.task_execution_handler\n  File \"python/ray/_raylet.pyx\", line 1045, in ray._raylet.execute_task_with_cancellation_handler\n  File \"python/ray/_raylet.pyx\", line 782, in ray._raylet.execute_task\n  File \"python/ray/_raylet.pyx\", line 945, in ray._raylet.execute_task\n  File \"python/ray/_raylet.pyx\", line 575, in ray._raylet.store_task_errors\n  File \"/usr/local/lib/python3.8/site-packages/ray/util/tracing/tracing_helper.py\", line 466, in _resume_span\n    return method(self, *_args, **_kwargs)\n  File \"/usr/local/lib/python3.8/site-packages/secretflow/device/device/spu.py\", line 379, in __repr__\n    return f\"SPURuntime(device_id={self.id}, party={self.party})\"\nAttributeError: 'SPURuntime' object has no attribute 'id'\nAn unexpected internal error occurred while the worker was executing a task.",
      "\nDuring handling of the above exception, another exception occurred:\n",
      "\u001b[0;31mSystemExit\u001b[0m                                Traceback (most recent call last)",
      "    \u001b[0;31m[... skipping hidden 1 frame]\u001b[0m\n",
      "File \u001b[0;32m/usr/local/lib/python3.8/site-packages/IPython/core/interactiveshell.py:2105\u001b[0m, in \u001b[0;36mInteractiveShell.showtraceback\u001b[0;34m(self, exc_tuple, filename, tb_offset, exception_only, running_compiled_code)\u001b[0m\n\u001b[1;32m   2103\u001b[0m         stb \u001b[38;5;241m=\u001b[39m value\u001b[38;5;241m.\u001b[39m_render_traceback_()\n\u001b[1;32m   2104\u001b[0m     \u001b[38;5;28;01melse\u001b[39;00m:\n\u001b[0;32m-> 2105\u001b[0m         stb \u001b[38;5;241m=\u001b[39m \u001b[38;5;28;43mself\u001b[39;49m\u001b[38;5;241;43m.\u001b[39;49m\u001b[43mInteractiveTB\u001b[49m\u001b[38;5;241;43m.\u001b[39;49m\u001b[43mstructured_traceback\u001b[49m\u001b[43m(\u001b[49m\n\u001b[1;32m   2106\u001b[0m \u001b[43m            \u001b[49m\u001b[43metype\u001b[49m\u001b[43m,\u001b[49m\u001b[43m \u001b[49m\u001b[43mvalue\u001b[49m\u001b[43m,\u001b[49m\u001b[43m \u001b[49m\u001b[43mtb\u001b[49m\u001b[43m,\u001b[49m\u001b[43m \u001b[49m\u001b[43mtb_offset\u001b[49m\u001b[38;5;241;43m=\u001b[39;49m\u001b[43mtb_offset\u001b[49m\n\u001b[1;32m   2107\u001b[0m \u001b[43m        \u001b[49m\u001b[43m)\u001b[49m\n\u001b[1;32m   2109\u001b[0m \u001b[38;5;28;01mexcept\u001b[39;00m \u001b[38;5;167;01mException\u001b[39;00m:\n\u001b[1;32m   2110\u001b[0m     \u001b[38;5;28mprint\u001b[39m(\n\u001b[1;32m   2111\u001b[0m         \u001b[38;5;124m\"\u001b[39m\u001b[38;5;124mUnexpected exception formatting exception. Falling back to standard exception\u001b[39m\u001b[38;5;124m\"\u001b[39m\n\u001b[1;32m   2112\u001b[0m     )\n",
      "File \u001b[0;32m/usr/local/lib/python3.8/site-packages/IPython/core/ultratb.py:1396\u001b[0m, in \u001b[0;36mAutoFormattedTB.structured_traceback\u001b[0;34m(self, etype, evalue, etb, tb_offset, number_of_lines_of_context)\u001b[0m\n\u001b[1;32m   1394\u001b[0m \u001b[38;5;28;01melse\u001b[39;00m:\n\u001b[1;32m   1395\u001b[0m     \u001b[38;5;28mself\u001b[39m\u001b[38;5;241m.\u001b[39mtb \u001b[38;5;241m=\u001b[39m etb\n\u001b[0;32m-> 1396\u001b[0m \u001b[38;5;28;01mreturn\u001b[39;00m \u001b[43mFormattedTB\u001b[49m\u001b[38;5;241;43m.\u001b[39;49m\u001b[43mstructured_traceback\u001b[49m\u001b[43m(\u001b[49m\n\u001b[1;32m   1397\u001b[0m \u001b[43m    \u001b[49m\u001b[38;5;28;43mself\u001b[39;49m\u001b[43m,\u001b[49m\u001b[43m \u001b[49m\u001b[43metype\u001b[49m\u001b[43m,\u001b[49m\u001b[43m \u001b[49m\u001b[43mevalue\u001b[49m\u001b[43m,\u001b[49m\u001b[43m \u001b[49m\u001b[43metb\u001b[49m\u001b[43m,\u001b[49m\u001b[43m \u001b[49m\u001b[43mtb_offset\u001b[49m\u001b[43m,\u001b[49m\u001b[43m \u001b[49m\u001b[43mnumber_of_lines_of_context\u001b[49m\n\u001b[1;32m   1398\u001b[0m \u001b[43m\u001b[49m\u001b[43m)\u001b[49m\n",
      "File \u001b[0;32m/usr/local/lib/python3.8/site-packages/IPython/core/ultratb.py:1287\u001b[0m, in \u001b[0;36mFormattedTB.structured_traceback\u001b[0;34m(self, etype, value, tb, tb_offset, number_of_lines_of_context)\u001b[0m\n\u001b[1;32m   1284\u001b[0m mode \u001b[38;5;241m=\u001b[39m \u001b[38;5;28mself\u001b[39m\u001b[38;5;241m.\u001b[39mmode\n\u001b[1;32m   1285\u001b[0m \u001b[38;5;28;01mif\u001b[39;00m mode \u001b[38;5;129;01min\u001b[39;00m \u001b[38;5;28mself\u001b[39m\u001b[38;5;241m.\u001b[39mverbose_modes:\n\u001b[1;32m   1286\u001b[0m     \u001b[38;5;66;03m# Verbose modes need a full traceback\u001b[39;00m\n\u001b[0;32m-> 1287\u001b[0m     \u001b[38;5;28;01mreturn\u001b[39;00m \u001b[43mVerboseTB\u001b[49m\u001b[38;5;241;43m.\u001b[39;49m\u001b[43mstructured_traceback\u001b[49m\u001b[43m(\u001b[49m\n\u001b[1;32m   1288\u001b[0m \u001b[43m        \u001b[49m\u001b[38;5;28;43mself\u001b[39;49m\u001b[43m,\u001b[49m\u001b[43m \u001b[49m\u001b[43metype\u001b[49m\u001b[43m,\u001b[49m\u001b[43m \u001b[49m\u001b[43mvalue\u001b[49m\u001b[43m,\u001b[49m\u001b[43m \u001b[49m\u001b[43mtb\u001b[49m\u001b[43m,\u001b[49m\u001b[43m \u001b[49m\u001b[43mtb_offset\u001b[49m\u001b[43m,\u001b[49m\u001b[43m \u001b[49m\u001b[43mnumber_of_lines_of_context\u001b[49m\n\u001b[1;32m   1289\u001b[0m \u001b[43m    \u001b[49m\u001b[43m)\u001b[49m\n\u001b[1;32m   1290\u001b[0m \u001b[38;5;28;01melif\u001b[39;00m mode \u001b[38;5;241m==\u001b[39m \u001b[38;5;124m'\u001b[39m\u001b[38;5;124mMinimal\u001b[39m\u001b[38;5;124m'\u001b[39m:\n\u001b[1;32m   1291\u001b[0m     \u001b[38;5;28;01mreturn\u001b[39;00m ListTB\u001b[38;5;241m.\u001b[39mget_exception_only(\u001b[38;5;28mself\u001b[39m, etype, value)\n",
      "File \u001b[0;32m/usr/local/lib/python3.8/site-packages/IPython/core/ultratb.py:1140\u001b[0m, in \u001b[0;36mVerboseTB.structured_traceback\u001b[0;34m(self, etype, evalue, etb, tb_offset, number_of_lines_of_context)\u001b[0m\n\u001b[1;32m   1131\u001b[0m \u001b[38;5;28;01mdef\u001b[39;00m \u001b[38;5;21mstructured_traceback\u001b[39m(\n\u001b[1;32m   1132\u001b[0m     \u001b[38;5;28mself\u001b[39m,\n\u001b[1;32m   1133\u001b[0m     etype: \u001b[38;5;28mtype\u001b[39m,\n\u001b[0;32m   (...)\u001b[0m\n\u001b[1;32m   1137\u001b[0m     number_of_lines_of_context: \u001b[38;5;28mint\u001b[39m \u001b[38;5;241m=\u001b[39m \u001b[38;5;241m5\u001b[39m,\n\u001b[1;32m   1138\u001b[0m ):\n\u001b[1;32m   1139\u001b[0m \u001b[38;5;250m    \u001b[39m\u001b[38;5;124;03m\"\"\"Return a nice text document describing the traceback.\"\"\"\u001b[39;00m\n\u001b[0;32m-> 1140\u001b[0m     formatted_exception \u001b[38;5;241m=\u001b[39m \u001b[38;5;28;43mself\u001b[39;49m\u001b[38;5;241;43m.\u001b[39;49m\u001b[43mformat_exception_as_a_whole\u001b[49m\u001b[43m(\u001b[49m\u001b[43metype\u001b[49m\u001b[43m,\u001b[49m\u001b[43m \u001b[49m\u001b[43mevalue\u001b[49m\u001b[43m,\u001b[49m\u001b[43m \u001b[49m\u001b[43metb\u001b[49m\u001b[43m,\u001b[49m\u001b[43m \u001b[49m\u001b[43mnumber_of_lines_of_context\u001b[49m\u001b[43m,\u001b[49m\n\u001b[1;32m   1141\u001b[0m \u001b[43m                                                           \u001b[49m\u001b[43mtb_offset\u001b[49m\u001b[43m)\u001b[49m\n\u001b[1;32m   1143\u001b[0m     colors \u001b[38;5;241m=\u001b[39m \u001b[38;5;28mself\u001b[39m\u001b[38;5;241m.\u001b[39mColors  \u001b[38;5;66;03m# just a shorthand + quicker name lookup\u001b[39;00m\n\u001b[1;32m   1144\u001b[0m     colorsnormal \u001b[38;5;241m=\u001b[39m colors\u001b[38;5;241m.\u001b[39mNormal  \u001b[38;5;66;03m# used a lot\u001b[39;00m\n",
      "File \u001b[0;32m/usr/local/lib/python3.8/site-packages/IPython/core/ultratb.py:1030\u001b[0m, in \u001b[0;36mVerboseTB.format_exception_as_a_whole\u001b[0;34m(self, etype, evalue, etb, number_of_lines_of_context, tb_offset)\u001b[0m\n\u001b[1;32m   1027\u001b[0m \u001b[38;5;28;01massert\u001b[39;00m \u001b[38;5;28misinstance\u001b[39m(tb_offset, \u001b[38;5;28mint\u001b[39m)\n\u001b[1;32m   1028\u001b[0m head \u001b[38;5;241m=\u001b[39m \u001b[38;5;28mself\u001b[39m\u001b[38;5;241m.\u001b[39mprepare_header(\u001b[38;5;28mstr\u001b[39m(etype), \u001b[38;5;28mself\u001b[39m\u001b[38;5;241m.\u001b[39mlong_header)\n\u001b[1;32m   1029\u001b[0m records \u001b[38;5;241m=\u001b[39m (\n\u001b[0;32m-> 1030\u001b[0m     \u001b[38;5;28;43mself\u001b[39;49m\u001b[38;5;241;43m.\u001b[39;49m\u001b[43mget_records\u001b[49m\u001b[43m(\u001b[49m\u001b[43metb\u001b[49m\u001b[43m,\u001b[49m\u001b[43m \u001b[49m\u001b[43mnumber_of_lines_of_context\u001b[49m\u001b[43m,\u001b[49m\u001b[43m \u001b[49m\u001b[43mtb_offset\u001b[49m\u001b[43m)\u001b[49m \u001b[38;5;28;01mif\u001b[39;00m etb \u001b[38;5;28;01melse\u001b[39;00m []\n\u001b[1;32m   1031\u001b[0m )\n\u001b[1;32m   1033\u001b[0m frames \u001b[38;5;241m=\u001b[39m []\n\u001b[1;32m   1034\u001b[0m skipped \u001b[38;5;241m=\u001b[39m \u001b[38;5;241m0\u001b[39m\n",
      "File \u001b[0;32m/usr/local/lib/python3.8/site-packages/IPython/core/ultratb.py:1098\u001b[0m, in \u001b[0;36mVerboseTB.get_records\u001b[0;34m(self, etb, number_of_lines_of_context, tb_offset)\u001b[0m\n\u001b[1;32m   1096\u001b[0m \u001b[38;5;28;01mwhile\u001b[39;00m cf \u001b[38;5;129;01mis\u001b[39;00m \u001b[38;5;129;01mnot\u001b[39;00m \u001b[38;5;28;01mNone\u001b[39;00m:\n\u001b[1;32m   1097\u001b[0m     \u001b[38;5;28;01mtry\u001b[39;00m:\n\u001b[0;32m-> 1098\u001b[0m         mod \u001b[38;5;241m=\u001b[39m \u001b[43minspect\u001b[49m\u001b[38;5;241;43m.\u001b[39;49m\u001b[43mgetmodule\u001b[49m\u001b[43m(\u001b[49m\u001b[43mcf\u001b[49m\u001b[38;5;241;43m.\u001b[39;49m\u001b[43mtb_frame\u001b[49m\u001b[43m)\u001b[49m\n\u001b[1;32m   1099\u001b[0m         \u001b[38;5;28;01mif\u001b[39;00m mod \u001b[38;5;129;01mis\u001b[39;00m \u001b[38;5;129;01mnot\u001b[39;00m \u001b[38;5;28;01mNone\u001b[39;00m:\n\u001b[1;32m   1100\u001b[0m             mod_name \u001b[38;5;241m=\u001b[39m mod\u001b[38;5;241m.\u001b[39m\u001b[38;5;18m__name__\u001b[39m\n",
      "File \u001b[0;32m/usr/local/lib/python3.8/inspect.py:754\u001b[0m, in \u001b[0;36mgetmodule\u001b[0;34m(object, _filename)\u001b[0m\n\u001b[1;32m    751\u001b[0m         f \u001b[38;5;241m=\u001b[39m getabsfile(module)\n\u001b[1;32m    752\u001b[0m         \u001b[38;5;66;03m# Always map to the name the module knows itself by\u001b[39;00m\n\u001b[1;32m    753\u001b[0m         modulesbyfile[f] \u001b[38;5;241m=\u001b[39m modulesbyfile[\n\u001b[0;32m--> 754\u001b[0m             \u001b[43mos\u001b[49m\u001b[38;5;241;43m.\u001b[39;49m\u001b[43mpath\u001b[49m\u001b[38;5;241;43m.\u001b[39;49m\u001b[43mrealpath\u001b[49m\u001b[43m(\u001b[49m\u001b[43mf\u001b[49m\u001b[43m)\u001b[49m] \u001b[38;5;241m=\u001b[39m module\u001b[38;5;241m.\u001b[39m\u001b[38;5;18m__name__\u001b[39m\n\u001b[1;32m    755\u001b[0m \u001b[38;5;28;01mif\u001b[39;00m file \u001b[38;5;129;01min\u001b[39;00m modulesbyfile:\n\u001b[1;32m    756\u001b[0m     \u001b[38;5;28;01mreturn\u001b[39;00m sys\u001b[38;5;241m.\u001b[39mmodules\u001b[38;5;241m.\u001b[39mget(modulesbyfile[file])\n",
      "File \u001b[0;32m/usr/local/lib/python3.8/posixpath.py:391\u001b[0m, in \u001b[0;36mrealpath\u001b[0;34m(filename)\u001b[0m\n\u001b[1;32m    388\u001b[0m \u001b[38;5;250m    \u001b[39m\u001b[38;5;124;03m\"\"\"Return the canonical path of the specified filename, eliminating any\u001b[39;00m\n\u001b[1;32m    389\u001b[0m \u001b[38;5;124;03msymbolic links encountered in the path.\"\"\"\u001b[39;00m\n\u001b[1;32m    390\u001b[0m     filename \u001b[38;5;241m=\u001b[39m os\u001b[38;5;241m.\u001b[39mfspath(filename)\n\u001b[0;32m--> 391\u001b[0m     path, ok \u001b[38;5;241m=\u001b[39m \u001b[43m_joinrealpath\u001b[49m\u001b[43m(\u001b[49m\u001b[43mfilename\u001b[49m\u001b[43m[\u001b[49m\u001b[43m:\u001b[49m\u001b[38;5;241;43m0\u001b[39;49m\u001b[43m]\u001b[49m\u001b[43m,\u001b[49m\u001b[43m \u001b[49m\u001b[43mfilename\u001b[49m\u001b[43m,\u001b[49m\u001b[43m \u001b[49m\u001b[43m{\u001b[49m\u001b[43m}\u001b[49m\u001b[43m)\u001b[49m\n\u001b[1;32m    392\u001b[0m     \u001b[38;5;28;01mreturn\u001b[39;00m abspath(path)\n",
      "File \u001b[0;32m/usr/local/lib/python3.8/posixpath.py:425\u001b[0m, in \u001b[0;36m_joinrealpath\u001b[0;34m(path, rest, seen)\u001b[0m\n\u001b[1;32m    423\u001b[0m     \u001b[38;5;28;01mcontinue\u001b[39;00m\n\u001b[1;32m    424\u001b[0m newpath \u001b[38;5;241m=\u001b[39m join(path, name)\n\u001b[0;32m--> 425\u001b[0m \u001b[38;5;28;01mif\u001b[39;00m \u001b[38;5;129;01mnot\u001b[39;00m \u001b[43mislink\u001b[49m\u001b[43m(\u001b[49m\u001b[43mnewpath\u001b[49m\u001b[43m)\u001b[49m:\n\u001b[1;32m    426\u001b[0m     path \u001b[38;5;241m=\u001b[39m newpath\n\u001b[1;32m    427\u001b[0m     \u001b[38;5;28;01mcontinue\u001b[39;00m\n",
      "File \u001b[0;32m/usr/local/lib/python3.8/posixpath.py:167\u001b[0m, in \u001b[0;36mislink\u001b[0;34m(path)\u001b[0m\n\u001b[1;32m    165\u001b[0m \u001b[38;5;250m\u001b[39m\u001b[38;5;124;03m\"\"\"Test whether a path is a symbolic link\"\"\"\u001b[39;00m\n\u001b[1;32m    166\u001b[0m \u001b[38;5;28;01mtry\u001b[39;00m:\n\u001b[0;32m--> 167\u001b[0m     st \u001b[38;5;241m=\u001b[39m \u001b[43mos\u001b[49m\u001b[38;5;241;43m.\u001b[39;49m\u001b[43mlstat\u001b[49m\u001b[43m(\u001b[49m\u001b[43mpath\u001b[49m\u001b[43m)\u001b[49m\n\u001b[1;32m    168\u001b[0m \u001b[38;5;28;01mexcept\u001b[39;00m (\u001b[38;5;167;01mOSError\u001b[39;00m, \u001b[38;5;167;01mValueError\u001b[39;00m, \u001b[38;5;167;01mAttributeError\u001b[39;00m):\n\u001b[1;32m    169\u001b[0m     \u001b[38;5;28;01mreturn\u001b[39;00m \u001b[38;5;28;01mFalse\u001b[39;00m\n",
      "File \u001b[0;32m/usr/local/lib/python3.8/site-packages/ray/_private/worker.py:1640\u001b[0m, in \u001b[0;36msigterm_handler\u001b[0;34m(signum, frame)\u001b[0m\n\u001b[1;32m   1639\u001b[0m \u001b[38;5;28;01mdef\u001b[39;00m \u001b[38;5;21msigterm_handler\u001b[39m(signum, frame):\n\u001b[0;32m-> 1640\u001b[0m     \u001b[43msys\u001b[49m\u001b[38;5;241;43m.\u001b[39;49m\u001b[43mexit\u001b[49m\u001b[43m(\u001b[49m\u001b[43msignum\u001b[49m\u001b[43m)\u001b[49m\n",
      "\u001b[0;31mSystemExit\u001b[0m: 15"
     ]
    },
    {
     "data": {
      "text/html": [
       "<h4>Bob's Output:</h4>"
      ]
     },
     "metadata": {},
     "output_type": "display_data"
    },
    {
     "name": "stderr",
     "output_type": "stream",
     "text": [
      "2023-10-10 05:18:26,340\tWARNING worker.py:1851 -- Traceback (most recent call last):\n",
      "  File \"python/ray/_raylet.pyx\", line 823, in ray._raylet.execute_task\n",
      "  File \"python/ray/_raylet.pyx\", line 875, in ray._raylet.execute_task\n",
      "  File \"python/ray/_raylet.pyx\", line 830, in ray._raylet.execute_task\n",
      "  File \"python/ray/_raylet.pyx\", line 834, in ray._raylet.execute_task\n",
      "  File \"python/ray/_raylet.pyx\", line 780, in ray._raylet.execute_task.function_executor\n",
      "  File \"/usr/local/lib/python3.8/site-packages/ray/_private/function_manager.py\", line 674, in actor_method_executor\n",
      "    return method(__ray_actor, *args, **kwargs)\n",
      "  File \"/usr/local/lib/python3.8/site-packages/ray/util/tracing/tracing_helper.py\", line 466, in _resume_span\n",
      "    return method(self, *_args, **_kwargs)\n",
      "  File \"/usr/local/lib/python3.8/site-packages/secretflow/device/device/spu.py\", line 370, in __init__\n",
      "    self.link = spu_link.create_brpc(desc, rank)\n",
      "RuntimeError: what: \n",
      "\t[external/yacl/yacl/link/transport/brpc_link.cc:130] brpc server failed start\n",
      "Stacktrace:\n",
      "#0 yacl::link::FactoryBrpc::CreateContext()+0x7f4337ac5799\n",
      "#1 pybind11::cpp_function::initialize<>()::{lambda()#3}::_FUN()+0x7f43365ecad6\n",
      "#2 pybind11::cpp_function::dispatcher()+0x7f43365cf1c6\n",
      "#3 PyCFunction_Call+0x4e0212\n",
      "\n",
      "stacktrace: \n",
      "#0 yacl::link::FactoryBrpc::CreateContext()+0x7f4337ac5799\n",
      "#1 pybind11::cpp_function::initialize<>()::{lambda()#3}::_FUN()+0x7f43365ecad6\n",
      "#2 pybind11::cpp_function::dispatcher()+0x7f43365cf1c6\n",
      "#3 PyCFunction_Call+0x4e0212\n",
      "\n",
      "\n",
      "\n",
      "During handling of the above exception, another exception occurred:\n",
      "\n",
      "Traceback (most recent call last):\n",
      "  File \"python/ray/_raylet.pyx\", line 1135, in ray._raylet.task_execution_handler\n",
      "  File \"python/ray/_raylet.pyx\", line 1045, in ray._raylet.execute_task_with_cancellation_handler\n",
      "  File \"python/ray/_raylet.pyx\", line 782, in ray._raylet.execute_task\n",
      "  File \"python/ray/_raylet.pyx\", line 945, in ray._raylet.execute_task\n",
      "  File \"python/ray/_raylet.pyx\", line 575, in ray._raylet.store_task_errors\n",
      "  File \"/usr/local/lib/python3.8/site-packages/ray/util/tracing/tracing_helper.py\", line 466, in _resume_span\n",
      "    return method(self, *_args, **_kwargs)\n",
      "  File \"/usr/local/lib/python3.8/site-packages/secretflow/device/device/spu.py\", line 379, in __repr__\n",
      "    return f\"SPURuntime(device_id={self.id}, party={self.party})\"\n",
      "AttributeError: 'SPURuntime' object has no attribute 'id'\n",
      "An unexpected internal error occurred while the worker was executing a task.\n",
      "2023-10-10 05:18:26,344\tWARNING worker.py:1851 -- A worker died or was killed while executing a task by an unexpected system error. To troubleshoot the problem, check the logs for the dead worker. RayTask ID: ffffffffffffffff4c27e5a576a7f5ed4cf278bf02000000 Worker ID: 065d0e7208e49ea2692c8b825e2d496a309475a1d64b8c3c7bfaae98 Node ID: 8871018bd030fde1635d48819bd875eab214910b48928400116b43b3 Worker IP address: 172.21.0.3 Worker port: 10009 Worker PID: 683 Worker exit type: SYSTEM_ERROR Worker exit detail: Worker exits unexpectedly. Worker exits with an exit code None.\n",
      " Traceback (most recent call last):\n",
      "  File \"python/ray/_raylet.pyx\", line 823, in ray._raylet.execute_task\n",
      "  File \"python/ray/_raylet.pyx\", line 875, in ray._raylet.execute_task\n",
      "  File \"python/ray/_raylet.pyx\", line 830, in ray._raylet.execute_task\n",
      "  File \"python/ray/_raylet.pyx\", line 834, in ray._raylet.execute_task\n",
      "  File \"python/ray/_raylet.pyx\", line 780, in ray._raylet.execute_task.function_executor\n",
      "  File \"/usr/local/lib/python3.8/site-packages/ray/_private/function_manager.py\", line 674, in actor_method_executor\n",
      "    return method(__ray_actor, *args, **kwargs)\n",
      "  File \"/usr/local/lib/python3.8/site-packages/ray/util/tracing/tracing_helper.py\", line 466, in _resume_span\n",
      "    return method(self, *_args, **_kwargs)\n",
      "  File \"/usr/local/lib/python3.8/site-packages/secretflow/device/device/spu.py\", line 370, in __init__\n",
      "    self.link = spu_link.create_brpc(desc, rank)\n",
      "RuntimeError: what: \n",
      "\t[external/yacl/yacl/link/transport/brpc_link.cc:130] brpc server failed start\n",
      "Stacktrace:\n",
      "#0 yacl::link::FactoryBrpc::CreateContext()+0x7f4337ac5799\n",
      "#1 pybind11::cpp_function::initialize<>()::{lambda()#3}::_FUN()+0x7f43365ecad6\n",
      "#2 pybind11::cpp_function::dispatcher()+0x7f43365cf1c6\n",
      "#3 PyCFunction_Call+0x4e0212\n",
      "\n",
      "stacktrace: \n",
      "#0 yacl::link::FactoryBrpc::CreateContext()+0x7f4337ac5799\n",
      "#1 pybind11::cpp_function::initialize<>()::{lambda()#3}::_FUN()+0x7f43365ecad6\n",
      "#2 pybind11::cpp_function::dispatcher()+0x7f43365cf1c6\n",
      "#3 PyCFunction_Call+0x4e0212\n",
      "\n",
      "\n",
      "\n",
      "During handling of the above exception, another exception occurred:\n",
      "\n",
      "Traceback (most recent call last):\n",
      "  File \"python/ray/_raylet.pyx\", line 1135, in ray._raylet.task_execution_handler\n",
      "  File \"python/ray/_raylet.pyx\", line 1045, in ray._raylet.execute_task_with_cancellation_handler\n",
      "  File \"python/ray/_raylet.pyx\", line 782, in ray._raylet.execute_task\n",
      "  File \"python/ray/_raylet.pyx\", line 945, in ray._raylet.execute_task\n",
      "  File \"python/ray/_raylet.pyx\", line 575, in ray._raylet.store_task_errors\n",
      "  File \"/usr/local/lib/python3.8/site-packages/ray/util/tracing/tracing_helper.py\", line 466, in _resume_span\n",
      "    return method(self, *_args, **_kwargs)\n",
      "  File \"/usr/local/lib/python3.8/site-packages/secretflow/device/device/spu.py\", line 379, in __repr__\n",
      "    return f\"SPURuntime(device_id={self.id}, party={self.party})\"\n",
      "AttributeError: 'SPURuntime' object has no attribute 'id'\n",
      "An unexpected internal error occurred while the worker was executing a task.\n",
      "2023-10-10 05:18:26 WARNING cleanup.py:99 [bob] --  Failed to send ObjectRef(0021899358e75e3c9befabcd882e585b40b020b40200000001000000) with error: \u001b[36mray::SenderProxyActor.send()\u001b[39m (pid=640, ip=172.21.0.3, repr=<fed.proxy.barriers.SenderProxyActor object at 0x7f77c408e310>)\n",
      "  At least one of the input arguments for this task could not be computed:\n",
      "ray.exceptions.RayActorError: The actor died unexpectedly before finishing this task.\n",
      "\tclass_name: SPURuntime\n",
      "\tactor_id: 4c27e5a576a7f5ed4cf278bf02000000\n",
      "\tpid: 683\n",
      "\tnamespace: 7210a617-9c9a-4fff-a098-39cd64f2eb10\n",
      "\tip: 172.21.0.3\n",
      "The actor is dead because its worker process has died. Worker exit type: SYSTEM_ERROR Worker exit detail: Worker exits unexpectedly. Worker exits with an exit code None.\n",
      " Traceback (most recent call last):\n",
      "  File \"/usr/local/lib/python3.8/site-packages/secretflow/device/device/spu.py\", line 370, in __init__\n",
      "    self.link = spu_link.create_brpc(desc, rank)\n",
      "RuntimeError: what: \n",
      "\t[external/yacl/yacl/link/transport/brpc_link.cc:130] brpc server failed start\n",
      "Stacktrace:\n",
      "#0 yacl::link::FactoryBrpc::CreateContext()+0x7f4337ac5799\n",
      "#1 pybind11::cpp_function::initialize<>()::{lambda()#3}::_FUN()+0x7f43365ecad6\n",
      "#2 pybind11::cpp_function::dispatcher()+0x7f43365cf1c6\n",
      "#3 PyCFunction_Call+0x4e0212\n",
      "\n",
      "stacktrace: \n",
      "#0 yacl::link::FactoryBrpc::CreateContext()+0x7f4337ac5799\n",
      "#1 pybind11::cpp_function::initialize<>()::{lambda()#3}::_FUN()+0x7f43365ecad6\n",
      "#2 pybind11::cpp_function::dispatcher()+0x7f43365cf1c6\n",
      "#3 PyCFunction_Call+0x4e0212\n",
      "\n",
      "\n",
      "\n",
      "During handling of the above exception, another exception occurred:\n",
      "\n",
      "\u001b[36mray::SenderProxyActor.send()\u001b[39m (pid=640, ip=172.21.0.3, repr=<fed.proxy.barriers.SenderProxyActor object at 0x7f77c408e310>)\n",
      "  File \"/usr/local/lib/python3.8/site-packages/secretflow/device/device/spu.py\", line 379, in __repr__\n",
      "    return f\"SPURuntime(device_id={self.id}, party={self.party})\"\n",
      "AttributeError: 'SPURuntime' object has no attribute 'id'\n",
      "An unexpected internal error occurred while the worker was executing a task.\n",
      "2023-10-10 05:18:26 WARNING cleanup.py:102 [bob] --  Signal self to exit.\n",
      "2023-10-10 05:18:26 INFO cleanup.py:106 [bob] --  Check sending thread was exited.\n",
      "*** SIGTERM received at time=1696915106 on cpu 0 ***\n",
      "PC: @     0x7f663c61182d  (unknown)  __lll_lock_wait\n",
      "    @     0x7f663c612cf0  (unknown)  (unknown)\n",
      "[2023-10-10 05:18:26,355 E 527 527] logging.cc:361: *** SIGTERM received at time=1696915106 on cpu 0 ***\n",
      "[2023-10-10 05:18:26,355 E 527 527] logging.cc:361: PC: @     0x7f663c61182d  (unknown)  __lll_lock_wait\n",
      "[2023-10-10 05:18:26,355 E 527 527] logging.cc:361:     @     0x7f663c612cf0  (unknown)  (unknown)\n",
      "\u001b[2m\u001b[36m(SPURuntime pid=683)\u001b[0m 2023-10-10 05:18:26,338\tERROR worker.py:763 -- Worker exits with an exit code None.\n",
      "\u001b[2m\u001b[36m(SPURuntime pid=683)\u001b[0m  Traceback (most recent call last):\n",
      "\u001b[2m\u001b[36m(SPURuntime pid=683)\u001b[0m   File \"python/ray/_raylet.pyx\", line 823, in ray._raylet.execute_task\n",
      "\u001b[2m\u001b[36m(SPURuntime pid=683)\u001b[0m   File \"python/ray/_raylet.pyx\", line 875, in ray._raylet.execute_task\n",
      "\u001b[2m\u001b[36m(SPURuntime pid=683)\u001b[0m   File \"python/ray/_raylet.pyx\", line 830, in ray._raylet.execute_task\n",
      "\u001b[2m\u001b[36m(SPURuntime pid=683)\u001b[0m   File \"python/ray/_raylet.pyx\", line 834, in ray._raylet.execute_task\n",
      "\u001b[2m\u001b[36m(SPURuntime pid=683)\u001b[0m   File \"python/ray/_raylet.pyx\", line 780, in ray._raylet.execute_task.function_executor\n",
      "\u001b[2m\u001b[36m(SPURuntime pid=683)\u001b[0m   File \"/usr/local/lib/python3.8/site-packages/ray/_private/function_manager.py\", line 674, in actor_method_executor\n",
      "\u001b[2m\u001b[36m(SPURuntime pid=683)\u001b[0m     return method(__ray_actor, *args, **kwargs)\n",
      "\u001b[2m\u001b[36m(SPURuntime pid=683)\u001b[0m   File \"/usr/local/lib/python3.8/site-packages/ray/util/tracing/tracing_helper.py\", line 466, in _resume_span\n",
      "\u001b[2m\u001b[36m(SPURuntime pid=683)\u001b[0m     return method(self, *_args, **_kwargs)\n",
      "\u001b[2m\u001b[36m(SPURuntime pid=683)\u001b[0m   File \"/usr/local/lib/python3.8/site-packages/secretflow/device/device/spu.py\", line 370, in __init__\n",
      "\u001b[2m\u001b[36m(SPURuntime pid=683)\u001b[0m     self.link = spu_link.create_brpc(desc, rank)\n",
      "\u001b[2m\u001b[36m(SPURuntime pid=683)\u001b[0m RuntimeError: what: \n",
      "\u001b[2m\u001b[36m(SPURuntime pid=683)\u001b[0m \t[external/yacl/yacl/link/transport/brpc_link.cc:130] brpc server failed start\n",
      "\u001b[2m\u001b[36m(SPURuntime pid=683)\u001b[0m Stacktrace:\n",
      "\u001b[2m\u001b[36m(SPURuntime pid=683)\u001b[0m #0 yacl::link::FactoryBrpc::CreateContext()+0x7f4337ac5799\n",
      "\u001b[2m\u001b[36m(SPURuntime pid=683)\u001b[0m #1 pybind11::cpp_function::initialize<>()::{lambda()#3}::_FUN()+0x7f43365ecad6\n",
      "\u001b[2m\u001b[36m(SPURuntime pid=683)\u001b[0m #2 pybind11::cpp_function::dispatcher()+0x7f43365cf1c6\n",
      "\u001b[2m\u001b[36m(SPURuntime pid=683)\u001b[0m #3 PyCFunction_Call+0x4e0212\n",
      "\u001b[2m\u001b[36m(SPURuntime pid=683)\u001b[0m \n",
      "\u001b[2m\u001b[36m(SPURuntime pid=683)\u001b[0m stacktrace: \n",
      "\u001b[2m\u001b[36m(SPURuntime pid=683)\u001b[0m #0 yacl::link::FactoryBrpc::CreateContext()+0x7f4337ac5799\n",
      "\u001b[2m\u001b[36m(SPURuntime pid=683)\u001b[0m #1 pybind11::cpp_function::initialize<>()::{lambda()#3}::_FUN()+0x7f43365ecad6\n",
      "\u001b[2m\u001b[36m(SPURuntime pid=683)\u001b[0m #2 pybind11::cpp_function::dispatcher()+0x7f43365cf1c6\n",
      "\u001b[2m\u001b[36m(SPURuntime pid=683)\u001b[0m #3 PyCFunction_Call+0x4e0212\n",
      "\u001b[2m\u001b[36m(SPURuntime pid=683)\u001b[0m \n",
      "\u001b[2m\u001b[36m(SPURuntime pid=683)\u001b[0m \n",
      "\u001b[2m\u001b[36m(SPURuntime pid=683)\u001b[0m \n",
      "\u001b[2m\u001b[36m(SPURuntime pid=683)\u001b[0m During handling of the above exception, another exception occurred:\n",
      "\u001b[2m\u001b[36m(SPURuntime pid=683)\u001b[0m \n",
      "\u001b[2m\u001b[36m(SPURuntime pid=683)\u001b[0m Traceback (most recent call last):\n",
      "\u001b[2m\u001b[36m(SPURuntime pid=683)\u001b[0m   File \"python/ray/_raylet.pyx\", line 1135, in ray._raylet.task_execution_handler\n",
      "\u001b[2m\u001b[36m(SPURuntime pid=683)\u001b[0m   File \"python/ray/_raylet.pyx\", line 1045, in ray._raylet.execute_task_with_cancellation_handler\n",
      "\u001b[2m\u001b[36m(SPURuntime pid=683)\u001b[0m   File \"python/ray/_raylet.pyx\", line 782, in ray._raylet.execute_task\n",
      "\u001b[2m\u001b[36m(SPURuntime pid=683)\u001b[0m   File \"python/ray/_raylet.pyx\", line 945, in ray._raylet.execute_task\n",
      "\u001b[2m\u001b[36m(SPURuntime pid=683)\u001b[0m   File \"python/ray/_raylet.pyx\", line 575, in ray._raylet.store_task_errors\n",
      "\u001b[2m\u001b[36m(SPURuntime pid=683)\u001b[0m   File \"/usr/local/lib/python3.8/site-packages/ray/util/tracing/tracing_helper.py\", line 466, in _resume_span\n",
      "\u001b[2m\u001b[36m(SPURuntime pid=683)\u001b[0m     return method(self, *_args, **_kwargs)\n",
      "\u001b[2m\u001b[36m(SPURuntime pid=683)\u001b[0m   File \"/usr/local/lib/python3.8/site-packages/secretflow/device/device/spu.py\", line 379, in __repr__\n",
      "\u001b[2m\u001b[36m(SPURuntime pid=683)\u001b[0m     return f\"SPURuntime(device_id={self.id}, party={self.party})\"\n",
      "\u001b[2m\u001b[36m(SPURuntime pid=683)\u001b[0m AttributeError: 'SPURuntime' object has no attribute 'id'\n",
      "\u001b[2m\u001b[36m(SPURuntime pid=683)\u001b[0m An unexpected internal error occurred while the worker was executing a task.\n",
      "\u001b[2m\u001b[36m(SPURuntime pid=683)\u001b[0m Traceback (most recent call last):\n",
      "\u001b[2m\u001b[36m(SPURuntime pid=683)\u001b[0m   File \"python/ray/_raylet.pyx\", line 823, in ray._raylet.execute_task\n",
      "\u001b[2m\u001b[36m(SPURuntime pid=683)\u001b[0m   File \"python/ray/_raylet.pyx\", line 875, in ray._raylet.execute_task\n",
      "\u001b[2m\u001b[36m(SPURuntime pid=683)\u001b[0m   File \"python/ray/_raylet.pyx\", line 830, in ray._raylet.execute_task\n",
      "\u001b[2m\u001b[36m(SPURuntime pid=683)\u001b[0m   File \"python/ray/_raylet.pyx\", line 834, in ray._raylet.execute_task\n",
      "\u001b[2m\u001b[36m(SPURuntime pid=683)\u001b[0m   File \"python/ray/_raylet.pyx\", line 780, in ray._raylet.execute_task.function_executor\n",
      "\u001b[2m\u001b[36m(SPURuntime pid=683)\u001b[0m   File \"/usr/local/lib/python3.8/site-packages/ray/_private/function_manager.py\", line 674, in actor_method_executor\n",
      "\u001b[2m\u001b[36m(SPURuntime pid=683)\u001b[0m     return method(__ray_actor, *args, **kwargs)\n",
      "\u001b[2m\u001b[36m(SPURuntime pid=683)\u001b[0m   File \"/usr/local/lib/python3.8/site-packages/ray/util/tracing/tracing_helper.py\", line 466, in _resume_span\n",
      "\u001b[2m\u001b[36m(SPURuntime pid=683)\u001b[0m     return method(self, *_args, **_kwargs)\n",
      "\u001b[2m\u001b[36m(SPURuntime pid=683)\u001b[0m   File \"/usr/local/lib/python3.8/site-packages/secretflow/device/device/spu.py\", line 370, in __init__\n",
      "\u001b[2m\u001b[36m(SPURuntime pid=683)\u001b[0m     self.link = spu_link.create_brpc(desc, rank)\n",
      "\u001b[2m\u001b[36m(SPURuntime pid=683)\u001b[0m RuntimeError: what: \n",
      "\u001b[2m\u001b[36m(SPURuntime pid=683)\u001b[0m \t[external/yacl/yacl/link/transport/brpc_link.cc:130] brpc server failed start\n",
      "\u001b[2m\u001b[36m(SPURuntime pid=683)\u001b[0m Stacktrace:\n",
      "\u001b[2m\u001b[36m(SPURuntime pid=683)\u001b[0m #0 yacl::link::FactoryBrpc::CreateContext()+0x7f4337ac5799\n",
      "\u001b[2m\u001b[36m(SPURuntime pid=683)\u001b[0m #1 pybind11::cpp_function::initialize<>()::{lambda()#3}::_FUN()+0x7f43365ecad6\n",
      "\u001b[2m\u001b[36m(SPURuntime pid=683)\u001b[0m #2 pybind11::cpp_function::dispatcher()+0x7f43365cf1c6\n",
      "\u001b[2m\u001b[36m(SPURuntime pid=683)\u001b[0m #3 PyCFunction_Call+0x4e0212\n",
      "\u001b[2m\u001b[36m(SPURuntime pid=683)\u001b[0m \n",
      "\u001b[2m\u001b[36m(SPURuntime pid=683)\u001b[0m stacktrace: \n",
      "\u001b[2m\u001b[36m(SPURuntime pid=683)\u001b[0m #0 yacl::link::FactoryBrpc::CreateContext()+0x7f4337ac5799\n",
      "\u001b[2m\u001b[36m(SPURuntime pid=683)\u001b[0m #1 pybind11::cpp_function::initialize<>()::{lambda()#3}::_FUN()+0x7f43365ecad6\n",
      "\u001b[2m\u001b[36m(SPURuntime pid=683)\u001b[0m #2 pybind11::cpp_function::dispatcher()+0x7f43365cf1c6\n",
      "\u001b[2m\u001b[36m(SPURuntime pid=683)\u001b[0m #3 PyCFunction_Call+0x4e0212\n",
      "\u001b[2m\u001b[36m(SPURuntime pid=683)\u001b[0m \n",
      "\u001b[2m\u001b[36m(SPURuntime pid=683)\u001b[0m \n",
      "\u001b[2m\u001b[36m(SPURuntime pid=683)\u001b[0m \n",
      "\u001b[2m\u001b[36m(SPURuntime pid=683)\u001b[0m During handling of the above exception, another exception occurred:\n",
      "\u001b[2m\u001b[36m(SPURuntime pid=683)\u001b[0m \n",
      "\u001b[2m\u001b[36m(SPURuntime pid=683)\u001b[0m Traceback (most recent call last):\n",
      "\u001b[2m\u001b[36m(SPURuntime pid=683)\u001b[0m   File \"python/ray/_raylet.pyx\", line 1135, in ray._raylet.task_execution_handler\n",
      "\u001b[2m\u001b[36m(SPURuntime pid=683)\u001b[0m   File \"python/ray/_raylet.pyx\", line 1045, in ray._raylet.execute_task_with_cancellation_handler\n",
      "\u001b[2m\u001b[36m(SPURuntime pid=683)\u001b[0m   File \"python/ray/_raylet.pyx\", line 782, in ray._raylet.execute_task\n",
      "\u001b[2m\u001b[36m(SPURuntime pid=683)\u001b[0m   File \"python/ray/_raylet.pyx\", line 945, in ray._raylet.execute_task\n",
      "\u001b[2m\u001b[36m(SPURuntime pid=683)\u001b[0m   File \"python/ray/_raylet.pyx\", line 575, in ray._raylet.store_task_errors\n",
      "\u001b[2m\u001b[36m(SPURuntime pid=683)\u001b[0m   File \"/usr/local/lib/python3.8/site-packages/ray/util/tracing/tracing_helper.py\", line 466, in _resume_span\n",
      "\u001b[2m\u001b[36m(SPURuntime pid=683)\u001b[0m     return method(self, *_args, **_kwargs)\n",
      "\u001b[2m\u001b[36m(SPURuntime pid=683)\u001b[0m   File \"/usr/local/lib/python3.8/site-packages/secretflow/device/device/spu.py\", line 379, in __repr__\n",
      "\u001b[2m\u001b[36m(SPURuntime pid=683)\u001b[0m     return f\"SPURuntime(device_id={self.id}, party={self.party})\"\n",
      "\u001b[2m\u001b[36m(SPURuntime pid=683)\u001b[0m AttributeError: 'SPURuntime' object has no attribute 'id'\n",
      "\u001b[2m\u001b[36m(SPURuntime pid=683)\u001b[0m \n",
      "\u001b[2m\u001b[36m(SPURuntime pid=683)\u001b[0m During handling of the above exception, another exception occurred:\n",
      "\u001b[2m\u001b[36m(SPURuntime pid=683)\u001b[0m \n",
      "\u001b[2m\u001b[36m(SPURuntime pid=683)\u001b[0m Traceback (most recent call last):\n",
      "\u001b[2m\u001b[36m(SPURuntime pid=683)\u001b[0m   File \"python/ray/_raylet.pyx\", line 1176, in ray._raylet.task_execution_handler\n",
      "\u001b[2m\u001b[36m(SPURuntime pid=683)\u001b[0m SystemExit\n"
     ]
    },
    {
     "name": "stdout",
     "output_type": "stream",
     "text": [
      "\u001b[2m\u001b[36m(SPURuntime pid=683)\u001b[0m 2023-10-10 05:18:26.321 [error] [server.cpp:BRPC:1023] Fail to listen 172.21.0.2:8081\n",
      "\u001b[2m\u001b[36m(SPURuntime pid=683)\u001b[0m 2023-10-10 05:18:26.337 [warning] [channel.h:~Channel:151] Channel destructor is called before WaitLinkTaskFinish, try stop send thread\n"
     ]
    },
    {
     "ename": "SystemExit",
     "evalue": "15",
     "output_type": "error",
     "traceback": [
      "\u001b[0;31m---------------------------------------------------------------------------\u001b[0m",
      "\u001b[0;31mRayActorError\u001b[0m                             Traceback (most recent call last)",
      "    \u001b[0;31m[... skipping hidden 1 frame]\u001b[0m\n",
      "Cell \u001b[0;32mIn[4], line 7\u001b[0m\n\u001b[1;32m      6\u001b[0m output_path \u001b[38;5;241m=\u001b[39m {alice: \u001b[38;5;124mf\u001b[39m\u001b[38;5;124m'\u001b[39m\u001b[38;5;132;01m{\u001b[39;00mcurrent_dir\u001b[38;5;132;01m}\u001b[39;00m\u001b[38;5;124m/iris_alice_psi.csv\u001b[39m\u001b[38;5;124m'\u001b[39m, bob: \u001b[38;5;124mf\u001b[39m\u001b[38;5;124m'\u001b[39m\u001b[38;5;132;01m{\u001b[39;00mcurrent_dir\u001b[38;5;132;01m}\u001b[39;00m\u001b[38;5;124m/iris_alice_psi.csv\u001b[39m\u001b[38;5;124m'\u001b[39m}\n\u001b[0;32m----> 7\u001b[0m \u001b[43mspu\u001b[49m\u001b[38;5;241;43m.\u001b[39;49m\u001b[43mpsi_csv\u001b[49m\u001b[43m(\u001b[49m\u001b[38;5;124;43m'\u001b[39;49m\u001b[38;5;124;43muid\u001b[39;49m\u001b[38;5;124;43m'\u001b[39;49m\u001b[43m,\u001b[49m\u001b[43m \u001b[49m\u001b[43minput_path\u001b[49m\u001b[43m,\u001b[49m\u001b[43m \u001b[49m\u001b[43moutput_path\u001b[49m\u001b[43m,\u001b[49m\u001b[43m \u001b[49m\u001b[38;5;124;43m'\u001b[39;49m\u001b[38;5;124;43malice\u001b[39;49m\u001b[38;5;124;43m'\u001b[39;49m\u001b[43m)\u001b[49m\n",
      "File \u001b[0;32m/usr/local/lib/python3.8/site-packages/secretflow/device/device/spu.py:1978\u001b[0m, in \u001b[0;36mSPU.psi_csv\u001b[0;34m(self, key, input_path, output_path, receiver, protocol, precheck_input, sort, broadcast_result, bucket_size, curve_type, preprocess_path, ecdh_secret_key_path, dppsi_bob_sub_sampling, dppsi_epsilon, progress_callbacks, callbacks_interval_ms)\u001b[0m\n\u001b[1;32m   1948\u001b[0m \u001b[38;5;250m\u001b[39m\u001b[38;5;124;03m\"\"\"Private set intersection with csv file.\u001b[39;00m\n\u001b[1;32m   1949\u001b[0m \n\u001b[1;32m   1950\u001b[0m \u001b[38;5;124;03mArgs:\u001b[39;00m\n\u001b[0;32m   (...)\u001b[0m\n\u001b[1;32m   1975\u001b[0m \u001b[38;5;124;03m    List[Dict]: PSI reports output by SPU with order reserved.\u001b[39;00m\n\u001b[1;32m   1976\u001b[0m \u001b[38;5;124;03m\"\"\"\u001b[39;00m\n\u001b[0;32m-> 1978\u001b[0m \u001b[38;5;28;01mreturn\u001b[39;00m \u001b[43mdispatch\u001b[49m\u001b[43m(\u001b[49m\n\u001b[1;32m   1979\u001b[0m \u001b[43m    \u001b[49m\u001b[38;5;124;43m'\u001b[39;49m\u001b[38;5;124;43mpsi_csv\u001b[39;49m\u001b[38;5;124;43m'\u001b[39;49m\u001b[43m,\u001b[49m\n\u001b[1;32m   1980\u001b[0m \u001b[43m    \u001b[49m\u001b[38;5;28;43mself\u001b[39;49m\u001b[43m,\u001b[49m\n\u001b[1;32m   1981\u001b[0m \u001b[43m    \u001b[49m\u001b[43mkey\u001b[49m\u001b[43m,\u001b[49m\n\u001b[1;32m   1982\u001b[0m \u001b[43m    \u001b[49m\u001b[43minput_path\u001b[49m\u001b[43m,\u001b[49m\n\u001b[1;32m   1983\u001b[0m \u001b[43m    \u001b[49m\u001b[43moutput_path\u001b[49m\u001b[43m,\u001b[49m\n\u001b[1;32m   1984\u001b[0m \u001b[43m    \u001b[49m\u001b[43mreceiver\u001b[49m\u001b[43m,\u001b[49m\n\u001b[1;32m   1985\u001b[0m \u001b[43m    \u001b[49m\u001b[43mprotocol\u001b[49m\u001b[43m,\u001b[49m\n\u001b[1;32m   1986\u001b[0m \u001b[43m    \u001b[49m\u001b[43mprecheck_input\u001b[49m\u001b[43m,\u001b[49m\n\u001b[1;32m   1987\u001b[0m \u001b[43m    \u001b[49m\u001b[43msort\u001b[49m\u001b[43m,\u001b[49m\n\u001b[1;32m   1988\u001b[0m \u001b[43m    \u001b[49m\u001b[43mbroadcast_result\u001b[49m\u001b[43m,\u001b[49m\n\u001b[1;32m   1989\u001b[0m \u001b[43m    \u001b[49m\u001b[43mbucket_size\u001b[49m\u001b[43m,\u001b[49m\n\u001b[1;32m   1990\u001b[0m \u001b[43m    \u001b[49m\u001b[43mcurve_type\u001b[49m\u001b[43m,\u001b[49m\n\u001b[1;32m   1991\u001b[0m \u001b[43m    \u001b[49m\u001b[43mpreprocess_path\u001b[49m\u001b[43m,\u001b[49m\n\u001b[1;32m   1992\u001b[0m \u001b[43m    \u001b[49m\u001b[43mecdh_secret_key_path\u001b[49m\u001b[43m,\u001b[49m\n\u001b[1;32m   1993\u001b[0m \u001b[43m    \u001b[49m\u001b[43mdppsi_bob_sub_sampling\u001b[49m\u001b[43m,\u001b[49m\n\u001b[1;32m   1994\u001b[0m \u001b[43m    \u001b[49m\u001b[43mdppsi_epsilon\u001b[49m\u001b[43m,\u001b[49m\n\u001b[1;32m   1995\u001b[0m \u001b[43m    \u001b[49m\u001b[43mprogress_callbacks\u001b[49m\u001b[43m,\u001b[49m\n\u001b[1;32m   1996\u001b[0m \u001b[43m    \u001b[49m\u001b[43mcallbacks_interval_ms\u001b[49m\u001b[43m,\u001b[49m\n\u001b[1;32m   1997\u001b[0m \u001b[43m\u001b[49m\u001b[43m)\u001b[49m\n",
      "File \u001b[0;32m/usr/local/lib/python3.8/site-packages/secretflow/device/device/register.py:111\u001b[0m, in \u001b[0;36mdispatch\u001b[0;34m(name, self, *args, **kwargs)\u001b[0m\n\u001b[1;32m    102\u001b[0m \u001b[38;5;250m\u001b[39m\u001b[38;5;124;03m\"\"\"Dispatch device kernel.\u001b[39;00m\n\u001b[1;32m    103\u001b[0m \n\u001b[1;32m    104\u001b[0m \u001b[38;5;124;03mArgs:\u001b[39;00m\n\u001b[0;32m   (...)\u001b[0m\n\u001b[1;32m    109\u001b[0m \u001b[38;5;124;03m    Kernel execution result.\u001b[39;00m\n\u001b[1;32m    110\u001b[0m \u001b[38;5;124;03m\"\"\"\u001b[39;00m\n\u001b[0;32m--> 111\u001b[0m \u001b[38;5;28;01mreturn\u001b[39;00m \u001b[43m_registrar\u001b[49m\u001b[38;5;241;43m.\u001b[39;49m\u001b[43mdispatch\u001b[49m\u001b[43m(\u001b[49m\u001b[38;5;28;43mself\u001b[39;49m\u001b[38;5;241;43m.\u001b[39;49m\u001b[43mdevice_type\u001b[49m\u001b[43m,\u001b[49m\u001b[43m \u001b[49m\u001b[43mname\u001b[49m\u001b[43m,\u001b[49m\u001b[43m \u001b[49m\u001b[38;5;28;43mself\u001b[39;49m\u001b[43m,\u001b[49m\u001b[43m \u001b[49m\u001b[38;5;241;43m*\u001b[39;49m\u001b[43margs\u001b[49m\u001b[43m,\u001b[49m\u001b[43m \u001b[49m\u001b[38;5;241;43m*\u001b[39;49m\u001b[38;5;241;43m*\u001b[39;49m\u001b[43mkwargs\u001b[49m\u001b[43m)\u001b[49m\n",
      "File \u001b[0;32m/usr/local/lib/python3.8/site-packages/secretflow/device/device/register.py:80\u001b[0m, in \u001b[0;36mRegistrar.dispatch\u001b[0;34m(self, device_type, name, *args, **kwargs)\u001b[0m\n\u001b[1;32m     79\u001b[0m     \u001b[38;5;28;01mraise\u001b[39;00m \u001b[38;5;167;01mKeyError\u001b[39;00m(\u001b[38;5;124mf\u001b[39m\u001b[38;5;124m'\u001b[39m\u001b[38;5;124mdevice: \u001b[39m\u001b[38;5;132;01m{\u001b[39;00mdevice_type\u001b[38;5;132;01m}\u001b[39;00m\u001b[38;5;124m, op: \u001b[39m\u001b[38;5;132;01m{\u001b[39;00mname\u001b[38;5;132;01m}\u001b[39;00m\u001b[38;5;124m not registered\u001b[39m\u001b[38;5;124m'\u001b[39m)\n\u001b[0;32m---> 80\u001b[0m \u001b[38;5;28;01mreturn\u001b[39;00m \u001b[38;5;28;43mself\u001b[39;49m\u001b[38;5;241;43m.\u001b[39;49m\u001b[43m_ops\u001b[49m\u001b[43m[\u001b[49m\u001b[43mdevice_type\u001b[49m\u001b[43m]\u001b[49m\u001b[43m[\u001b[49m\u001b[43mname\u001b[49m\u001b[43m]\u001b[49m\u001b[43m(\u001b[49m\u001b[38;5;241;43m*\u001b[39;49m\u001b[43margs\u001b[49m\u001b[43m,\u001b[49m\u001b[43m \u001b[49m\u001b[38;5;241;43m*\u001b[39;49m\u001b[38;5;241;43m*\u001b[39;49m\u001b[43mkwargs\u001b[49m\u001b[43m)\u001b[49m\n",
      "File \u001b[0;32m/usr/local/lib/python3.8/site-packages/secretflow/device/kernels/spu.py:318\u001b[0m, in \u001b[0;36mpsi_csv\u001b[0;34m(device, key, input_path, output_path, receiver, protocol, precheck_input, sort, broadcast_result, bucket_size, curve_type, preprocess_path, ecdh_secret_key_path, dppsi_bob_sub_sampling, dppsi_epsilon, progress_callbacks, callbacks_interval_ms)\u001b[0m\n\u001b[1;32m    317\u001b[0m \u001b[38;5;66;03m# wait for all tasks done\u001b[39;00m\n\u001b[0;32m--> 318\u001b[0m \u001b[38;5;28;01mreturn\u001b[39;00m \u001b[43msfd\u001b[49m\u001b[38;5;241;43m.\u001b[39;49m\u001b[43mget\u001b[49m\u001b[43m(\u001b[49m\u001b[43mres\u001b[49m\u001b[43m)\u001b[49m\n",
      "File \u001b[0;32m/usr/local/lib/python3.8/site-packages/secretflow/distributed/primitive.py:73\u001b[0m, in \u001b[0;36mget\u001b[0;34m(object_refs)\u001b[0m\n\u001b[1;32m     72\u001b[0m \u001b[38;5;28;01mif\u001b[39;00m production_mode():\n\u001b[0;32m---> 73\u001b[0m     \u001b[38;5;28;01mreturn\u001b[39;00m \u001b[43mfed\u001b[49m\u001b[38;5;241;43m.\u001b[39;49m\u001b[43mget\u001b[49m\u001b[43m(\u001b[49m\u001b[43mobject_refs\u001b[49m\u001b[43m)\u001b[49m\n\u001b[1;32m     74\u001b[0m \u001b[38;5;28;01melse\u001b[39;00m:\n",
      "File \u001b[0;32m/usr/local/lib/python3.8/site-packages/fed/api.py:395\u001b[0m, in \u001b[0;36mget\u001b[0;34m(fed_objects)\u001b[0m\n\u001b[1;32m    393\u001b[0m         ray_refs\u001b[38;5;241m.\u001b[39mappend(received_ray_object_ref)\n\u001b[0;32m--> 395\u001b[0m values \u001b[38;5;241m=\u001b[39m \u001b[43mray\u001b[49m\u001b[38;5;241;43m.\u001b[39;49m\u001b[43mget\u001b[49m\u001b[43m(\u001b[49m\u001b[43mray_refs\u001b[49m\u001b[43m)\u001b[49m\n\u001b[1;32m    396\u001b[0m \u001b[38;5;28;01mif\u001b[39;00m is_individual_id:\n",
      "File \u001b[0;32m/usr/local/lib/python3.8/site-packages/ray/_private/client_mode_hook.py:105\u001b[0m, in \u001b[0;36mclient_mode_hook.<locals>.wrapper\u001b[0;34m(*args, **kwargs)\u001b[0m\n\u001b[1;32m    104\u001b[0m         \u001b[38;5;28;01mreturn\u001b[39;00m \u001b[38;5;28mgetattr\u001b[39m(ray, func\u001b[38;5;241m.\u001b[39m\u001b[38;5;18m__name__\u001b[39m)(\u001b[38;5;241m*\u001b[39margs, \u001b[38;5;241m*\u001b[39m\u001b[38;5;241m*\u001b[39mkwargs)\n\u001b[0;32m--> 105\u001b[0m \u001b[38;5;28;01mreturn\u001b[39;00m \u001b[43mfunc\u001b[49m\u001b[43m(\u001b[49m\u001b[38;5;241;43m*\u001b[39;49m\u001b[43margs\u001b[49m\u001b[43m,\u001b[49m\u001b[43m \u001b[49m\u001b[38;5;241;43m*\u001b[39;49m\u001b[38;5;241;43m*\u001b[39;49m\u001b[43mkwargs\u001b[49m\u001b[43m)\u001b[49m\n",
      "File \u001b[0;32m/usr/local/lib/python3.8/site-packages/ray/_private/worker.py:2311\u001b[0m, in \u001b[0;36mget\u001b[0;34m(object_refs, timeout)\u001b[0m\n\u001b[1;32m   2310\u001b[0m         \u001b[38;5;28;01melse\u001b[39;00m:\n\u001b[0;32m-> 2311\u001b[0m             \u001b[38;5;28;01mraise\u001b[39;00m value\n\u001b[1;32m   2313\u001b[0m \u001b[38;5;28;01mif\u001b[39;00m is_individual_id:\n",
      "\u001b[0;31mRayActorError\u001b[0m: The actor died unexpectedly before finishing this task.\n\tclass_name: SPURuntime\n\tactor_id: 4c27e5a576a7f5ed4cf278bf02000000\n\tpid: 683\n\tnamespace: 7210a617-9c9a-4fff-a098-39cd64f2eb10\n\tip: 172.21.0.3\nThe actor is dead because its worker process has died. Worker exit type: SYSTEM_ERROR Worker exit detail: Worker exits unexpectedly. Worker exits with an exit code None.\n Traceback (most recent call last):\n  File \"python/ray/_raylet.pyx\", line 823, in ray._raylet.execute_task\n  File \"python/ray/_raylet.pyx\", line 875, in ray._raylet.execute_task\n  File \"python/ray/_raylet.pyx\", line 830, in ray._raylet.execute_task\n  File \"python/ray/_raylet.pyx\", line 834, in ray._raylet.execute_task\n  File \"python/ray/_raylet.pyx\", line 780, in ray._raylet.execute_task.function_executor\n  File \"/usr/local/lib/python3.8/site-packages/ray/_private/function_manager.py\", line 674, in actor_method_executor\n    return method(__ray_actor, *args, **kwargs)\n  File \"/usr/local/lib/python3.8/site-packages/ray/util/tracing/tracing_helper.py\", line 466, in _resume_span\n    return method(self, *_args, **_kwargs)\n  File \"/usr/local/lib/python3.8/site-packages/secretflow/device/device/spu.py\", line 370, in __init__\n    self.link = spu_link.create_brpc(desc, rank)\nRuntimeError: what: \n\t[external/yacl/yacl/link/transport/brpc_link.cc:130] brpc server failed start\nStacktrace:\n#0 yacl::link::FactoryBrpc::CreateContext()+0x7f4337ac5799\n#1 pybind11::cpp_function::initialize<>()::{lambda()#3}::_FUN()+0x7f43365ecad6\n#2 pybind11::cpp_function::dispatcher()+0x7f43365cf1c6\n#3 PyCFunction_Call+0x4e0212\n\nstacktrace: \n#0 yacl::link::FactoryBrpc::CreateContext()+0x7f4337ac5799\n#1 pybind11::cpp_function::initialize<>()::{lambda()#3}::_FUN()+0x7f43365ecad6\n#2 pybind11::cpp_function::dispatcher()+0x7f43365cf1c6\n#3 PyCFunction_Call+0x4e0212\n\n\n\nDuring handling of the above exception, another exception occurred:\n\nTraceback (most recent call last):\n  File \"python/ray/_raylet.pyx\", line 1135, in ray._raylet.task_execution_handler\n  File \"python/ray/_raylet.pyx\", line 1045, in ray._raylet.execute_task_with_cancellation_handler\n  File \"python/ray/_raylet.pyx\", line 782, in ray._raylet.execute_task\n  File \"python/ray/_raylet.pyx\", line 945, in ray._raylet.execute_task\n  File \"python/ray/_raylet.pyx\", line 575, in ray._raylet.store_task_errors\n  File \"/usr/local/lib/python3.8/site-packages/ray/util/tracing/tracing_helper.py\", line 466, in _resume_span\n    return method(self, *_args, **_kwargs)\n  File \"/usr/local/lib/python3.8/site-packages/secretflow/device/device/spu.py\", line 379, in __repr__\n    return f\"SPURuntime(device_id={self.id}, party={self.party})\"\nAttributeError: 'SPURuntime' object has no attribute 'id'\nAn unexpected internal error occurred while the worker was executing a task.",
      "\nDuring handling of the above exception, another exception occurred:\n",
      "\u001b[0;31mSystemExit\u001b[0m                                Traceback (most recent call last)",
      "    \u001b[0;31m[... skipping hidden 1 frame]\u001b[0m\n",
      "File \u001b[0;32m/usr/local/lib/python3.8/site-packages/IPython/core/interactiveshell.py:2105\u001b[0m, in \u001b[0;36mInteractiveShell.showtraceback\u001b[0;34m(self, exc_tuple, filename, tb_offset, exception_only, running_compiled_code)\u001b[0m\n\u001b[1;32m   2103\u001b[0m         stb \u001b[38;5;241m=\u001b[39m value\u001b[38;5;241m.\u001b[39m_render_traceback_()\n\u001b[1;32m   2104\u001b[0m     \u001b[38;5;28;01melse\u001b[39;00m:\n\u001b[0;32m-> 2105\u001b[0m         stb \u001b[38;5;241m=\u001b[39m \u001b[38;5;28;43mself\u001b[39;49m\u001b[38;5;241;43m.\u001b[39;49m\u001b[43mInteractiveTB\u001b[49m\u001b[38;5;241;43m.\u001b[39;49m\u001b[43mstructured_traceback\u001b[49m\u001b[43m(\u001b[49m\n\u001b[1;32m   2106\u001b[0m \u001b[43m            \u001b[49m\u001b[43metype\u001b[49m\u001b[43m,\u001b[49m\u001b[43m \u001b[49m\u001b[43mvalue\u001b[49m\u001b[43m,\u001b[49m\u001b[43m \u001b[49m\u001b[43mtb\u001b[49m\u001b[43m,\u001b[49m\u001b[43m \u001b[49m\u001b[43mtb_offset\u001b[49m\u001b[38;5;241;43m=\u001b[39;49m\u001b[43mtb_offset\u001b[49m\n\u001b[1;32m   2107\u001b[0m \u001b[43m        \u001b[49m\u001b[43m)\u001b[49m\n\u001b[1;32m   2109\u001b[0m \u001b[38;5;28;01mexcept\u001b[39;00m \u001b[38;5;167;01mException\u001b[39;00m:\n\u001b[1;32m   2110\u001b[0m     \u001b[38;5;28mprint\u001b[39m(\n\u001b[1;32m   2111\u001b[0m         \u001b[38;5;124m\"\u001b[39m\u001b[38;5;124mUnexpected exception formatting exception. Falling back to standard exception\u001b[39m\u001b[38;5;124m\"\u001b[39m\n\u001b[1;32m   2112\u001b[0m     )\n",
      "File \u001b[0;32m/usr/local/lib/python3.8/site-packages/IPython/core/ultratb.py:1396\u001b[0m, in \u001b[0;36mAutoFormattedTB.structured_traceback\u001b[0;34m(self, etype, evalue, etb, tb_offset, number_of_lines_of_context)\u001b[0m\n\u001b[1;32m   1394\u001b[0m \u001b[38;5;28;01melse\u001b[39;00m:\n\u001b[1;32m   1395\u001b[0m     \u001b[38;5;28mself\u001b[39m\u001b[38;5;241m.\u001b[39mtb \u001b[38;5;241m=\u001b[39m etb\n\u001b[0;32m-> 1396\u001b[0m \u001b[38;5;28;01mreturn\u001b[39;00m \u001b[43mFormattedTB\u001b[49m\u001b[38;5;241;43m.\u001b[39;49m\u001b[43mstructured_traceback\u001b[49m\u001b[43m(\u001b[49m\n\u001b[1;32m   1397\u001b[0m \u001b[43m    \u001b[49m\u001b[38;5;28;43mself\u001b[39;49m\u001b[43m,\u001b[49m\u001b[43m \u001b[49m\u001b[43metype\u001b[49m\u001b[43m,\u001b[49m\u001b[43m \u001b[49m\u001b[43mevalue\u001b[49m\u001b[43m,\u001b[49m\u001b[43m \u001b[49m\u001b[43metb\u001b[49m\u001b[43m,\u001b[49m\u001b[43m \u001b[49m\u001b[43mtb_offset\u001b[49m\u001b[43m,\u001b[49m\u001b[43m \u001b[49m\u001b[43mnumber_of_lines_of_context\u001b[49m\n\u001b[1;32m   1398\u001b[0m \u001b[43m\u001b[49m\u001b[43m)\u001b[49m\n",
      "File \u001b[0;32m/usr/local/lib/python3.8/site-packages/IPython/core/ultratb.py:1287\u001b[0m, in \u001b[0;36mFormattedTB.structured_traceback\u001b[0;34m(self, etype, value, tb, tb_offset, number_of_lines_of_context)\u001b[0m\n\u001b[1;32m   1284\u001b[0m mode \u001b[38;5;241m=\u001b[39m \u001b[38;5;28mself\u001b[39m\u001b[38;5;241m.\u001b[39mmode\n\u001b[1;32m   1285\u001b[0m \u001b[38;5;28;01mif\u001b[39;00m mode \u001b[38;5;129;01min\u001b[39;00m \u001b[38;5;28mself\u001b[39m\u001b[38;5;241m.\u001b[39mverbose_modes:\n\u001b[1;32m   1286\u001b[0m     \u001b[38;5;66;03m# Verbose modes need a full traceback\u001b[39;00m\n\u001b[0;32m-> 1287\u001b[0m     \u001b[38;5;28;01mreturn\u001b[39;00m \u001b[43mVerboseTB\u001b[49m\u001b[38;5;241;43m.\u001b[39;49m\u001b[43mstructured_traceback\u001b[49m\u001b[43m(\u001b[49m\n\u001b[1;32m   1288\u001b[0m \u001b[43m        \u001b[49m\u001b[38;5;28;43mself\u001b[39;49m\u001b[43m,\u001b[49m\u001b[43m \u001b[49m\u001b[43metype\u001b[49m\u001b[43m,\u001b[49m\u001b[43m \u001b[49m\u001b[43mvalue\u001b[49m\u001b[43m,\u001b[49m\u001b[43m \u001b[49m\u001b[43mtb\u001b[49m\u001b[43m,\u001b[49m\u001b[43m \u001b[49m\u001b[43mtb_offset\u001b[49m\u001b[43m,\u001b[49m\u001b[43m \u001b[49m\u001b[43mnumber_of_lines_of_context\u001b[49m\n\u001b[1;32m   1289\u001b[0m \u001b[43m    \u001b[49m\u001b[43m)\u001b[49m\n\u001b[1;32m   1290\u001b[0m \u001b[38;5;28;01melif\u001b[39;00m mode \u001b[38;5;241m==\u001b[39m \u001b[38;5;124m'\u001b[39m\u001b[38;5;124mMinimal\u001b[39m\u001b[38;5;124m'\u001b[39m:\n\u001b[1;32m   1291\u001b[0m     \u001b[38;5;28;01mreturn\u001b[39;00m ListTB\u001b[38;5;241m.\u001b[39mget_exception_only(\u001b[38;5;28mself\u001b[39m, etype, value)\n",
      "File \u001b[0;32m/usr/local/lib/python3.8/site-packages/IPython/core/ultratb.py:1140\u001b[0m, in \u001b[0;36mVerboseTB.structured_traceback\u001b[0;34m(self, etype, evalue, etb, tb_offset, number_of_lines_of_context)\u001b[0m\n\u001b[1;32m   1131\u001b[0m \u001b[38;5;28;01mdef\u001b[39;00m \u001b[38;5;21mstructured_traceback\u001b[39m(\n\u001b[1;32m   1132\u001b[0m     \u001b[38;5;28mself\u001b[39m,\n\u001b[1;32m   1133\u001b[0m     etype: \u001b[38;5;28mtype\u001b[39m,\n\u001b[0;32m   (...)\u001b[0m\n\u001b[1;32m   1137\u001b[0m     number_of_lines_of_context: \u001b[38;5;28mint\u001b[39m \u001b[38;5;241m=\u001b[39m \u001b[38;5;241m5\u001b[39m,\n\u001b[1;32m   1138\u001b[0m ):\n\u001b[1;32m   1139\u001b[0m \u001b[38;5;250m    \u001b[39m\u001b[38;5;124;03m\"\"\"Return a nice text document describing the traceback.\"\"\"\u001b[39;00m\n\u001b[0;32m-> 1140\u001b[0m     formatted_exception \u001b[38;5;241m=\u001b[39m \u001b[38;5;28;43mself\u001b[39;49m\u001b[38;5;241;43m.\u001b[39;49m\u001b[43mformat_exception_as_a_whole\u001b[49m\u001b[43m(\u001b[49m\u001b[43metype\u001b[49m\u001b[43m,\u001b[49m\u001b[43m \u001b[49m\u001b[43mevalue\u001b[49m\u001b[43m,\u001b[49m\u001b[43m \u001b[49m\u001b[43metb\u001b[49m\u001b[43m,\u001b[49m\u001b[43m \u001b[49m\u001b[43mnumber_of_lines_of_context\u001b[49m\u001b[43m,\u001b[49m\n\u001b[1;32m   1141\u001b[0m \u001b[43m                                                           \u001b[49m\u001b[43mtb_offset\u001b[49m\u001b[43m)\u001b[49m\n\u001b[1;32m   1143\u001b[0m     colors \u001b[38;5;241m=\u001b[39m \u001b[38;5;28mself\u001b[39m\u001b[38;5;241m.\u001b[39mColors  \u001b[38;5;66;03m# just a shorthand + quicker name lookup\u001b[39;00m\n\u001b[1;32m   1144\u001b[0m     colorsnormal \u001b[38;5;241m=\u001b[39m colors\u001b[38;5;241m.\u001b[39mNormal  \u001b[38;5;66;03m# used a lot\u001b[39;00m\n",
      "File \u001b[0;32m/usr/local/lib/python3.8/site-packages/IPython/core/ultratb.py:1030\u001b[0m, in \u001b[0;36mVerboseTB.format_exception_as_a_whole\u001b[0;34m(self, etype, evalue, etb, number_of_lines_of_context, tb_offset)\u001b[0m\n\u001b[1;32m   1027\u001b[0m \u001b[38;5;28;01massert\u001b[39;00m \u001b[38;5;28misinstance\u001b[39m(tb_offset, \u001b[38;5;28mint\u001b[39m)\n\u001b[1;32m   1028\u001b[0m head \u001b[38;5;241m=\u001b[39m \u001b[38;5;28mself\u001b[39m\u001b[38;5;241m.\u001b[39mprepare_header(\u001b[38;5;28mstr\u001b[39m(etype), \u001b[38;5;28mself\u001b[39m\u001b[38;5;241m.\u001b[39mlong_header)\n\u001b[1;32m   1029\u001b[0m records \u001b[38;5;241m=\u001b[39m (\n\u001b[0;32m-> 1030\u001b[0m     \u001b[38;5;28;43mself\u001b[39;49m\u001b[38;5;241;43m.\u001b[39;49m\u001b[43mget_records\u001b[49m\u001b[43m(\u001b[49m\u001b[43metb\u001b[49m\u001b[43m,\u001b[49m\u001b[43m \u001b[49m\u001b[43mnumber_of_lines_of_context\u001b[49m\u001b[43m,\u001b[49m\u001b[43m \u001b[49m\u001b[43mtb_offset\u001b[49m\u001b[43m)\u001b[49m \u001b[38;5;28;01mif\u001b[39;00m etb \u001b[38;5;28;01melse\u001b[39;00m []\n\u001b[1;32m   1031\u001b[0m )\n\u001b[1;32m   1033\u001b[0m frames \u001b[38;5;241m=\u001b[39m []\n\u001b[1;32m   1034\u001b[0m skipped \u001b[38;5;241m=\u001b[39m \u001b[38;5;241m0\u001b[39m\n",
      "File \u001b[0;32m/usr/local/lib/python3.8/site-packages/IPython/core/ultratb.py:1081\u001b[0m, in \u001b[0;36mVerboseTB.get_records\u001b[0;34m(self, etb, number_of_lines_of_context, tb_offset)\u001b[0m\n\u001b[1;32m   1079\u001b[0m before \u001b[38;5;241m=\u001b[39m context \u001b[38;5;241m-\u001b[39m after\n\u001b[1;32m   1080\u001b[0m \u001b[38;5;28;01mif\u001b[39;00m \u001b[38;5;28mself\u001b[39m\u001b[38;5;241m.\u001b[39mhas_colors:\n\u001b[0;32m-> 1081\u001b[0m     style \u001b[38;5;241m=\u001b[39m \u001b[43mget_style_by_name\u001b[49m\u001b[43m(\u001b[49m\u001b[38;5;124;43m\"\u001b[39;49m\u001b[38;5;124;43mdefault\u001b[39;49m\u001b[38;5;124;43m\"\u001b[39;49m\u001b[43m)\u001b[49m\n\u001b[1;32m   1082\u001b[0m     style \u001b[38;5;241m=\u001b[39m stack_data\u001b[38;5;241m.\u001b[39mstyle_with_executing_node(style, \u001b[38;5;28mself\u001b[39m\u001b[38;5;241m.\u001b[39m_tb_highlight)\n\u001b[1;32m   1083\u001b[0m     formatter \u001b[38;5;241m=\u001b[39m Terminal256Formatter(style\u001b[38;5;241m=\u001b[39mstyle)\n",
      "File \u001b[0;32m/usr/local/lib/python3.8/site-packages/pygments/styles/__init__.py:90\u001b[0m, in \u001b[0;36mget_style_by_name\u001b[0;34m(name)\u001b[0m\n\u001b[1;32m     87\u001b[0m     \u001b[38;5;28mcls\u001b[39m \u001b[38;5;241m=\u001b[39m name\u001b[38;5;241m.\u001b[39mtitle() \u001b[38;5;241m+\u001b[39m \u001b[38;5;124m\"\u001b[39m\u001b[38;5;124mStyle\u001b[39m\u001b[38;5;124m\"\u001b[39m\n\u001b[1;32m     89\u001b[0m \u001b[38;5;28;01mtry\u001b[39;00m:\n\u001b[0;32m---> 90\u001b[0m     mod \u001b[38;5;241m=\u001b[39m \u001b[38;5;28;43m__import__\u001b[39;49m\u001b[43m(\u001b[49m\u001b[38;5;124;43m'\u001b[39;49m\u001b[38;5;124;43mpygments.styles.\u001b[39;49m\u001b[38;5;124;43m'\u001b[39;49m\u001b[43m \u001b[49m\u001b[38;5;241;43m+\u001b[39;49m\u001b[43m \u001b[49m\u001b[43mmod\u001b[49m\u001b[43m,\u001b[49m\u001b[43m \u001b[49m\u001b[38;5;28;43;01mNone\u001b[39;49;00m\u001b[43m,\u001b[49m\u001b[43m \u001b[49m\u001b[38;5;28;43;01mNone\u001b[39;49;00m\u001b[43m,\u001b[49m\u001b[43m \u001b[49m\u001b[43m[\u001b[49m\u001b[38;5;28;43mcls\u001b[39;49m\u001b[43m]\u001b[49m\u001b[43m)\u001b[49m\n\u001b[1;32m     91\u001b[0m \u001b[38;5;28;01mexcept\u001b[39;00m \u001b[38;5;167;01mImportError\u001b[39;00m:\n\u001b[1;32m     92\u001b[0m     \u001b[38;5;28;01mraise\u001b[39;00m ClassNotFound(\u001b[38;5;124m\"\u001b[39m\u001b[38;5;124mCould not find style module \u001b[39m\u001b[38;5;132;01m%r\u001b[39;00m\u001b[38;5;124m\"\u001b[39m \u001b[38;5;241m%\u001b[39m mod \u001b[38;5;241m+\u001b[39m\n\u001b[1;32m     93\u001b[0m                      (builtin \u001b[38;5;129;01mand\u001b[39;00m \u001b[38;5;124m\"\u001b[39m\u001b[38;5;124m, though it should be builtin\u001b[39m\u001b[38;5;124m\"\u001b[39m) \u001b[38;5;241m+\u001b[39m \u001b[38;5;124m\"\u001b[39m\u001b[38;5;124m.\u001b[39m\u001b[38;5;124m\"\u001b[39m)\n",
      "File \u001b[0;32m<frozen importlib._bootstrap>:991\u001b[0m, in \u001b[0;36m_find_and_load\u001b[0;34m(name, import_)\u001b[0m\n",
      "File \u001b[0;32m<frozen importlib._bootstrap>:975\u001b[0m, in \u001b[0;36m_find_and_load_unlocked\u001b[0;34m(name, import_)\u001b[0m\n",
      "File \u001b[0;32m<frozen importlib._bootstrap>:671\u001b[0m, in \u001b[0;36m_load_unlocked\u001b[0;34m(spec)\u001b[0m\n",
      "File \u001b[0;32m<frozen importlib._bootstrap_external>:839\u001b[0m, in \u001b[0;36mexec_module\u001b[0;34m(self, module)\u001b[0m\n",
      "File \u001b[0;32m<frozen importlib._bootstrap_external>:934\u001b[0m, in \u001b[0;36mget_code\u001b[0;34m(self, fullname)\u001b[0m\n",
      "File \u001b[0;32m<frozen importlib._bootstrap_external>:1032\u001b[0m, in \u001b[0;36mget_data\u001b[0;34m(self, path)\u001b[0m\n",
      "File \u001b[0;32m/usr/local/lib/python3.8/site-packages/ray/_private/worker.py:1640\u001b[0m, in \u001b[0;36msigterm_handler\u001b[0;34m(signum, frame)\u001b[0m\n\u001b[1;32m   1639\u001b[0m \u001b[38;5;28;01mdef\u001b[39;00m \u001b[38;5;21msigterm_handler\u001b[39m(signum, frame):\n\u001b[0;32m-> 1640\u001b[0m     \u001b[43msys\u001b[49m\u001b[38;5;241;43m.\u001b[39;49m\u001b[43mexit\u001b[49m\u001b[43m(\u001b[49m\u001b[43msignum\u001b[49m\u001b[43m)\u001b[49m\n",
      "\u001b[0;31mSystemExit\u001b[0m: 15"
     ]
    }
   ],
   "source": [
    "import os\n",
    "\n",
    "current_dir = os.getcwd()\n",
    "\n",
    "input_path = {alice: f'{current_dir}/iris_alice.csv', bob: f'{current_dir}/iris_bob.csv'}\n",
    "output_path = {alice: f'{current_dir}/iris_alice_psi.csv', bob: f'{current_dir}/iris_alice_psi.csv'}\n",
    "spu.psi_csv('uid', input_path, output_path, 'alice')"
   ]
  },
  {
   "cell_type": "code",
   "execution_count": null,
   "id": "712ecb46-639f-40b9-902d-ac50df817ace",
   "metadata": {
    "execution": {
     "executionParty": "[\"1e1e72d3-844e-4ada-966e-d56bb5f217ed\",\"806a79e5-f708-4e3e-a0ff-e3ea0503a00a\"]",
     "shell.execute_reply.end": "2023-10-10T05:18:28.259520Z",
     "shell.execute_reply.started": "2023-10-10T05:18:27.888228Z",
     "to_execute": "2023-10-10T05:18:20.668Z"
    }
   },
   "outputs": [],
   "source": []
  }
 ],
 "metadata": {
  "language_info": {
   "name": "python"
  }
 },
 "nbformat": 4,
 "nbformat_minor": 5
}
